{}
2022-08-06 03:08:00
3
Trading for Ian
Trading for Stu
Trading for Nick
APIError(code=32110): It can only be requested once within 6 hour(s).
Trading for time: 2022-08-06 03:08:00 UTC  or 2022-08-05 23:08:00 EST
[5.709402, -5.409925]
{'WAXPBUSD': {'amnt': 920.91755085, 'price': 0.11420000344514847}}
{'EOSBUSD': {'amnt': 83.95755326, 'price': 1.253999948501587}}
{'OPBUSD': {'amnt': 54.98380324, 'price': 1.9160000085830688}}
{'FTMBUSD': {'amnt': 279.77385925, 'price': 0.37599998712539673}}
{'VETBUSD': {'amnt': 3325.75999211, 'price': 0.031619999557733536}}
{'symbol': 'ICPBUSD', 'origClientOrderId': 'u5FCJJ7gjCnQ0jp7TPzPUW', 'orderId': 208366244, 'orderListId': -1, 'clientOrderId': 'eQcQE8EDiaDrACcRwzWMxB', 'price': '8.42000000', 'origQty': '13.81000000', 'executedQty': '0.00000000', 'cummulativeQuoteQty': '0.00000000', 'status': 'CANCELED', 'timeInForce': 'GTC', 'type': 'LIMIT_MAKER', 'side': 'SELL'}
sell ATOMBUSD, 2.55
sell ATOMBUSD, 2.54
APIError(code=-2010): Account has insufficient balance for requested action.
sell ICPBUSD, 13.81
{'symbol': 'ICPBUSD', 'orderId': 208366259, 'orderListId': -1, 'clientOrderId': 'QCX40pvDUk5PHWwBYN9s1Z', 'transactTime': 1659755338223}
Completed {'ICPBUSD': 13.81}
buy WAXPBUSD, 921.0
{'symbol': 'WAXPBUSD', 'orderId': 63691162, 'orderListId': -1, 'clientOrderId': 'SAyzxbY5G6QT2zRUQK2h4z', 'transactTime': 1659755338552}
Completed {'WAXPBUSD': 920.91755085}
buy EOSBUSD, 84.0
{'symbol': 'EOSBUSD', 'orderId': 603856210, 'orderListId': -1, 'clientOrderId': 'bqaEx0bx5MVQXDm9ns7goX', 'transactTime': 1659755338883}
Completed {'EOSBUSD': 83.95755326}
buy OPBUSD, 54.98
{'symbol': 'OPBUSD', 'orderId': 72884375, 'orderListId': -1, 'clientOrderId': 'AnYukVO3yczVjKfk55cdW1', 'transactTime': 1659755339211}
Completed {'OPBUSD': 54.98380324}
buy FTMBUSD, 280.0
{'symbol': 'FTMBUSD', 'orderId': 509458950, 'orderListId': -1, 'clientOrderId': 'eXKKO37SxLpmv9xKGcSTSi', 'transactTime': 1659755339959}
Completed {'FTMBUSD': 279.77385925}
buy VETBUSD, 3325.8
APIError(code=-2010): Account has insufficient balance for requested action.
C:\Users\Ian\anaconda3\envs\qlbt\lib\site-packages\dateparser\date_parser.py:35: PytzUsageWarning:

The localize method is no longer necessary, as this time zone supports the fold attribute (PEP 495). For more details on migrating to a PEP 495-compliant implementation, see https://pytz-deprecation-shim.readthedocs.io/en/latest/migration.html

2022-08-05 23:08:19.551 | INFO     | data_pulling.dump_bin:_load_all_source_data:443 - start load all source data....
2022-08-05 23:08:19.604 | INFO     | data_pulling.dump_bin:_load_all_source_data:459 - end of load all data.

2022-08-05 23:08:19.717 | INFO     | data_pulling.dump_bin:_dump_features:469 - start dump features......
2022-08-05 23:08:19.744 | INFO     | data_pulling.dump_bin:_dump_features:505 - dump bin errors： {}
2022-08-05 23:08:19.744 | INFO     | data_pulling.dump_bin:_dump_features:507 - end of features dump.

[230104:MainThread](2022-08-05 23:08:19,753) INFO - qlib.Initialization - [config.py:401] - default_conf: client.
[230104:MainThread](2022-08-05 23:08:21,908) WARNING - qlib.Initialization - [config.py:426] - redis connection failed(host=127.0.0.1 port=6379), DiskExpressionCache and DiskDatasetCache will not be used!
[230104:MainThread](2022-08-05 23:08:22,250) INFO - qlib.Initialization - [__init__.py:74] - qlib successfully initialized based on client settings.
[230104:MainThread](2022-08-05 23:08:22,251) INFO - qlib.Initialization - [__init__.py:76] - data_path={'1min': WindowsPath('C:/Users/Ian/Documents/Financial testing/data_pulling/data-download/1m-qlib')}
  0%|          | 0/2 [00:00<?, ?it/s] 50%|█████     | 1/2 [00:10<00:10, 10.23s/it]100%|██████████| 2/2 [00:19<00:00,  9.90s/it]100%|██████████| 2/2 [00:19<00:00,  9.95s/it]
[230104:MainThread](2022-08-05 23:08:42,196) INFO - qlib.timer - [log.py:113] - Time cost: 19.910s | Loading data Done
[230104:MainThread](2022-08-05 23:08:42,197) INFO - qlib.timer - [log.py:113] - Time cost: 0.000s | fit & process data Done
[I 2022-08-05 23:08:55,968] Using an existing study with name 'backtest' instead of creating a new one.
{'ADABUSD': 'Traceback (most recent call last):\n  File "C:\\Users\\Ian\\Documents\\Financial testing\\data_pulling\\dump_bin.py", line 500, in _dump_features\n    _future.result()\n  File "C:\\Users\\Ian\\anaconda3\\envs\\qlbt\\lib\\concurrent\\futures\\_base.py", line 437, in result\n    return self.__get_result()\n  File "C:\\Users\\Ian\\anaconda3\\envs\\qlbt\\lib\\concurrent\\futures\\_base.py", line 389, in __get_result\n    raise self._exception\nconcurrent.futures.process.BrokenProcessPool: A process in the process pool was terminated abruptly while the future was running or pending.\n', 'ALGOBUSD': 'Traceback (most recent call last):\n  File "C:\\Users\\Ian\\Documents\\Financial testing\\data_pulling\\dump_bin.py", line 500, in _dump_features\n    _future.result()\n  File "C:\\Users\\Ian\\anaconda3\\envs\\qlbt\\lib\\concurrent\\futures\\_base.py", line 437, in result\n    return self.__get_result()\n  File "C:\\Users\\Ian\\anaconda3\\envs\\qlbt\\lib\\concurrent\\futures\\_base.py", line 389, in __get_result\n    raise self._exception\n  File "C:\\Users\\Ian\\Documents\\Financial testing\\data_pulling\\dump_bin.py", line 500, in _dump_features\n    _future.result()\n  File "C:\\Users\\Ian\\anaconda3\\envs\\qlbt\\lib\\concurrent\\futures\\_base.py", line 437, in result\n    return self.__get_result()\n  File "C:\\Users\\Ian\\anaconda3\\envs\\qlbt\\lib\\concurrent\\futures\\_base.py", line 389, in __get_result\n    raise self._exception\nconcurrent.futures.process.BrokenProcessPool: A process in the process pool was terminated abruptly while the future was running or pending.\n', 'ATOMBUSD': 'Traceback (most recent call last):\n  File "C:\\Users\\Ian\\Documents\\Financial testing\\data_pulling\\dump_bin.py", line 500, in _dump_features\n    _future.result()\n  File "C:\\Users\\Ian\\anaconda3\\envs\\qlbt\\lib\\concurrent\\futures\\_base.py", line 437, in result\n    return self.__get_result()\n  File "C:\\Users\\Ian\\anaconda3\\envs\\qlbt\\lib\\concurrent\\futures\\_base.py", line 389, in __get_result\n    raise self._exception\n  File "C:\\Users\\Ian\\Documents\\Financial testing\\data_pulling\\dump_bin.py", line 500, in _dump_features\n    _future.result()\n  File "C:\\Users\\Ian\\anaconda3\\envs\\qlbt\\lib\\concurrent\\futures\\_base.py", line 437, in result\n    return self.__get_result()\n  File "C:\\Users\\Ian\\anaconda3\\envs\\qlbt\\lib\\concurrent\\futures\\_base.py", line 389, in __get_result\n    raise self._exception\n  File "C:\\Users\\Ian\\Documents\\Financial testing\\data_pulling\\dump_bin.py", line 500, in _dump_features\n    _future.result()\n  File "C:\\Users\\Ian\\anaconda3\\envs\\qlbt\\lib\\concurrent\\futures\\_base.py", line 437, in result\n    return self.__get_result()\n  File "C:\\Users\\Ian\\anaconda3\\envs\\qlbt\\lib\\concurrent\\futures\\_base.py", line 389, in __get_result\n    raise self._exception\nconcurrent.futures.process.BrokenProcessPool: A process in the process pool was terminated abruptly while the future was running or pending.\n', 'AVAXBUSD': 'Traceback (most recent call last):\n  File "C:\\Users\\Ian\\Documents\\Financial testing\\data_pulling\\dump_bin.py", line 500, in _dump_features\n    _future.result()\n  File "C:\\Users\\Ian\\anaconda3\\envs\\qlbt\\lib\\concurrent\\futures\\_base.py", line 437, in result\n    return self.__get_result()\n  File "C:\\Users\\Ian\\anaconda3\\envs\\qlbt\\lib\\concurrent\\futures\\_base.py", line 389, in __get_result\n    raise self._exception\n  File "C:\\Users\\Ian\\Documents\\Financial testing\\data_pulling\\dump_bin.py", line 500, in _dump_features\n    _future.result()\n  File "C:\\Users\\Ian\\anaconda3\\envs\\qlbt\\lib\\concurrent\\futures\\_base.py", line 437, in result\n    return self.__get_result()\n  File "C:\\Users\\Ian\\anaconda3\\envs\\qlbt\\lib\\concurrent\\futures\\_base.py", line 389, in __get_result\n    raise self._exception\n  File "C:\\Users\\Ian\\Documents\\Financial testing\\data_pulling\\dump_bin.py", line 500, in _dump_features\n    _future.result()\n  File "C:\\Users\\Ian\\anaconda3\\envs\\qlbt\\lib\\concurrent\\futures\\_base.py", line 437, in result\n    return self.__get_result()\n  File "C:\\Users\\Ian\\anaconda3\\envs\\qlbt\\lib\\concurrent\\futures\\_base.py", line 389, in __get_result\n    raise self._exception\n  File "C:\\Users\\Ian\\Documents\\Financial testing\\data_pulling\\dump_bin.py", line 500, in _dump_features\n    _future.result()\n  File "C:\\Users\\Ian\\anaconda3\\envs\\qlbt\\lib\\concurrent\\futures\\_base.py", line 437, in result\n    return self.__get_result()\n  File "C:\\Users\\Ian\\anaconda3\\envs\\qlbt\\lib\\concurrent\\futures\\_base.py", line 389, in __get_result\n    raise self._exception\nconcurrent.futures.process.BrokenProcessPool: A process in the process pool was terminated abruptly while the future was running or pending.\n', 'BNBBUSD': 'Traceback (most recent call last):\n  File "C:\\Users\\Ian\\Documents\\Financial testing\\data_pulling\\dump_bin.py", line 500, in _dump_features\n    _future.result()\n  File "C:\\Users\\Ian\\anaconda3\\envs\\qlbt\\lib\\concurrent\\futures\\_base.py", line 437, in result\n    return self.__get_result()\n  File "C:\\Users\\Ian\\anaconda3\\envs\\qlbt\\lib\\concurrent\\futures\\_base.py", line 389, in __get_result\n    raise self._exception\n  File "C:\\Users\\Ian\\Documents\\Financial testing\\data_pulling\\dump_bin.py", line 500, in _dump_features\n    _future.result()\n  File "C:\\Users\\Ian\\anaconda3\\envs\\qlbt\\lib\\concurrent\\futures\\_base.py", line 437, in result\n    return self.__get_result()\n  File "C:\\Users\\Ian\\anaconda3\\envs\\qlbt\\lib\\concurrent\\futures\\_base.py", line 389, in __get_result\n    raise self._exception\n  File "C:\\Users\\Ian\\Documents\\Financial testing\\data_pulling\\dump_bin.py", line 500, in _dump_features\n    _future.result()\n  File "C:\\Users\\Ian\\anaconda3\\envs\\qlbt\\lib\\concurrent\\futures\\_base.py", line 437, in result\n    return self.__get_result()\n  File "C:\\Users\\Ian\\anaconda3\\envs\\qlbt\\lib\\concurrent\\futures\\_base.py", line 389, in __get_result\n    raise self._exception\n  File "C:\\Users\\Ian\\Documents\\Financial testing\\data_pulling\\dump_bin.py", line 500, in _dump_features\n    _future.result()\n  File "C:\\Users\\Ian\\anaconda3\\envs\\qlbt\\lib\\concurrent\\futures\\_base.py", line 437, in result\n    return self.__get_result()\n  File "C:\\Users\\Ian\\anaconda3\\envs\\qlbt\\lib\\concurrent\\futures\\_base.py", line 389, in __get_result\n    raise self._exception\n  File "C:\\Users\\Ian\\Documents\\Financial testing\\data_pulling\\dump_bin.py", line 500, in _dump_features\n    _future.result()\n  File "C:\\Users\\Ian\\anaconda3\\envs\\qlbt\\lib\\concurrent\\futures\\_base.py", line 437, in result\n    return self.__get_result()\n  File "C:\\Users\\Ian\\anaconda3\\envs\\qlbt\\lib\\concurrent\\futures\\_base.py", line 389, in __get_result\n    raise self._exception\nconcurrent.futures.process.BrokenProcessPool: A process in the process pool was terminated abruptly while the future was running or pending.\n', 'BTCBUSD': 'Traceback (most recent call last):\n  File "C:\\Users\\Ian\\Documents\\Financial testing\\data_pulling\\dump_bin.py", line 500, in _dump_features\n    _future.result()\n  File "C:\\Users\\Ian\\anaconda3\\envs\\qlbt\\lib\\concurrent\\futures\\_base.py", line 437, in result\n    return self.__get_result()\n  File "C:\\Users\\Ian\\anaconda3\\envs\\qlbt\\lib\\concurrent\\futures\\_base.py", line 389, in __get_result\n    raise self._exception\n  File "C:\\Users\\Ian\\Documents\\Financial testing\\data_pulling\\dump_bin.py", line 500, in _dump_features\n    _future.result()\n  File "C:\\Users\\Ian\\anaconda3\\envs\\qlbt\\lib\\concurrent\\futures\\_base.py", line 437, in result\n    return self.__get_result()\n  File "C:\\Users\\Ian\\anaconda3\\envs\\qlbt\\lib\\concurrent\\futures\\_base.py", line 389, in __get_result\n    raise self._exception\n  File "C:\\Users\\Ian\\Documents\\Financial testing\\data_pulling\\dump_bin.py", line 500, in _dump_features\n    _future.result()\n  File "C:\\Users\\Ian\\anaconda3\\envs\\qlbt\\lib\\concurrent\\futures\\_base.py", line 437, in result\n    return self.__get_result()\n  File "C:\\Users\\Ian\\anaconda3\\envs\\qlbt\\lib\\concurrent\\futures\\_base.py", line 389, in __get_result\n    raise self._exception\n  File "C:\\Users\\Ian\\Documents\\Financial testing\\data_pulling\\dump_bin.py", line 500, in _dump_features\n    _future.result()\n  File "C:\\Users\\Ian\\anaconda3\\envs\\qlbt\\lib\\concurrent\\futures\\_base.py", line 437, in result\n    return self.__get_result()\n  File "C:\\Users\\Ian\\anaconda3\\envs\\qlbt\\lib\\concurrent\\futures\\_base.py", line 389, in __get_result\n    raise self._exception\n  File "C:\\Users\\Ian\\Documents\\Financial testing\\data_pulling\\dump_bin.py", line 500, in _dump_features\n    _future.result()\n  File "C:\\Users\\Ian\\anaconda3\\envs\\qlbt\\lib\\concurrent\\futures\\_base.py", line 437, in result\n    return self.__get_result()\n  File "C:\\Users\\Ian\\anaconda3\\envs\\qlbt\\lib\\concurrent\\futures\\_base.py", line 389, in __get_result\n    raise self._exception\n  File "C:\\Users\\Ian\\Documents\\Financial testing\\data_pulling\\dump_bin.py", line 500, in _dump_features\n    _future.result()\n  File "C:\\Users\\Ian\\anaconda3\\envs\\qlbt\\lib\\concurrent\\futures\\_base.py", line 437, in result\n    return self.__get_result()\n  File "C:\\Users\\Ian\\anaconda3\\envs\\qlbt\\lib\\concurrent\\futures\\_base.py", line 389, in __get_result\n    raise self._exception\nconcurrent.futures.process.BrokenProcessPool: A process in the process pool was terminated abruptly while the future was running or pending.\n', 'DOTBUSD': 'Traceback (most recent call last):\n  File "C:\\Users\\Ian\\Documents\\Financial testing\\data_pulling\\dump_bin.py", line 500, in _dump_features\n    _future.result()\n  File "C:\\Users\\Ian\\anaconda3\\envs\\qlbt\\lib\\concurrent\\futures\\_base.py", line 437, in result\n    return self.__get_result()\n  File "C:\\Users\\Ian\\anaconda3\\envs\\qlbt\\lib\\concurrent\\futures\\_base.py", line 389, in __get_result\n    raise self._exception\n  File "C:\\Users\\Ian\\Documents\\Financial testing\\data_pulling\\dump_bin.py", line 500, in _dump_features\n    _future.result()\n  File "C:\\Users\\Ian\\anaconda3\\envs\\qlbt\\lib\\concurrent\\futures\\_base.py", line 437, in result\n    return self.__get_result()\n  File "C:\\Users\\Ian\\anaconda3\\envs\\qlbt\\lib\\concurrent\\futures\\_base.py", line 389, in __get_result\n    raise self._exception\n  File "C:\\Users\\Ian\\Documents\\Financial testing\\data_pulling\\dump_bin.py", line 500, in _dump_features\n    _future.result()\n  File "C:\\Users\\Ian\\anaconda3\\envs\\qlbt\\lib\\concurrent\\futures\\_base.py", line 437, in result\n    return self.__get_result()\n  File "C:\\Users\\Ian\\anaconda3\\envs\\qlbt\\lib\\concurrent\\futures\\_base.py", line 389, in __get_result\n    raise self._exception\n  File "C:\\Users\\Ian\\Documents\\Financial testing\\data_pulling\\dump_bin.py", line 500, in _dump_features\n    _future.result()\n  File "C:\\Users\\Ian\\anaconda3\\envs\\qlbt\\lib\\concurrent\\futures\\_base.py", line 437, in result\n    return self.__get_result()\n  File "C:\\Users\\Ian\\anaconda3\\envs\\qlbt\\lib\\concurrent\\futures\\_base.py", line 389, in __get_result\n    raise self._exception\n  File "C:\\Users\\Ian\\Documents\\Financial testing\\data_pulling\\dump_bin.py", line 500, in _dump_features\n    _future.result()\n  File "C:\\Users\\Ian\\anaconda3\\envs\\qlbt\\lib\\concurrent\\futures\\_base.py", line 437, in result\n    return self.__get_result()\n  File "C:\\Users\\Ian\\anaconda3\\envs\\qlbt\\lib\\concurrent\\futures\\_base.py", line 389, in __get_result\n    raise self._exception\n  File "C:\\Users\\Ian\\Documents\\Financial testing\\data_pulling\\dump_bin.py", line 500, in _dump_features\n    _future.result()\n  File "C:\\Users\\Ian\\anaconda3\\envs\\qlbt\\lib\\concurrent\\futures\\_base.py", line 437, in result\n    return self.__get_result()\n  File "C:\\Users\\Ian\\anaconda3\\envs\\qlbt\\lib\\concurrent\\futures\\_base.py", line 389, in __get_result\n    raise self._exception\n  File "C:\\Users\\Ian\\Documents\\Financial testing\\data_pulling\\dump_bin.py", line 500, in _dump_features\n    _future.result()\n  File "C:\\Users\\Ian\\anaconda3\\envs\\qlbt\\lib\\concurrent\\futures\\_base.py", line 437, in result\n    return self.__get_result()\n  File "C:\\Users\\Ian\\anaconda3\\envs\\qlbt\\lib\\concurrent\\futures\\_base.py", line 389, in __get_result\n    raise self._exception\nconcurrent.futures.process.BrokenProcessPool: A process in the process pool was terminated abruptly while the future was running or pending.\n', 'EOSBUSD': 'Traceback (most recent call last):\n  File "C:\\Users\\Ian\\Documents\\Financial testing\\data_pulling\\dump_bin.py", line 500, in _dump_features\n    _future.result()\n  File "C:\\Users\\Ian\\anaconda3\\envs\\qlbt\\lib\\concurrent\\futures\\_base.py", line 437, in result\n    return self.__get_result()\n  File "C:\\Users\\Ian\\anaconda3\\envs\\qlbt\\lib\\concurrent\\futures\\_base.py", line 389, in __get_result\n    raise self._exception\n  File "C:\\Users\\Ian\\Documents\\Financial testing\\data_pulling\\dump_bin.py", line 500, in _dump_features\n    _future.result()\n  File "C:\\Users\\Ian\\anaconda3\\envs\\qlbt\\lib\\concurrent\\futures\\_base.py", line 437, in result\n    return self.__get_result()\n  File "C:\\Users\\Ian\\anaconda3\\envs\\qlbt\\lib\\concurrent\\futures\\_base.py", line 389, in __get_result\n    raise self._exception\n  File "C:\\Users\\Ian\\Documents\\Financial testing\\data_pulling\\dump_bin.py", line 500, in _dump_features\n    _future.result()\n  File "C:\\Users\\Ian\\anaconda3\\envs\\qlbt\\lib\\concurrent\\futures\\_base.py", line 437, in result\n    return self.__get_result()\n  File "C:\\Users\\Ian\\anaconda3\\envs\\qlbt\\lib\\concurrent\\futures\\_base.py", line 389, in __get_result\n    raise self._exception\n  File "C:\\Users\\Ian\\Documents\\Financial testing\\data_pulling\\dump_bin.py", line 500, in _dump_features\n    _future.result()\n  File "C:\\Users\\Ian\\anaconda3\\envs\\qlbt\\lib\\concurrent\\futures\\_base.py", line 437, in result\n    return self.__get_result()\n  File "C:\\Users\\Ian\\anaconda3\\envs\\qlbt\\lib\\concurrent\\futures\\_base.py", line 389, in __get_result\n    raise self._exception\n  File "C:\\Users\\Ian\\Documents\\Financial testing\\data_pulling\\dump_bin.py", line 500, in _dump_features\n    _future.result()\n  File "C:\\Users\\Ian\\anaconda3\\envs\\qlbt\\lib\\concurrent\\futures\\_base.py", line 437, in result\n    return self.__get_result()\n  File "C:\\Users\\Ian\\anaconda3\\envs\\qlbt\\lib\\concurrent\\futures\\_base.py", line 389, in __get_result\n    raise self._exception\n  File "C:\\Users\\Ian\\Documents\\Financial testing\\data_pulling\\dump_bin.py", line 500, in _dump_features\n    _future.result()\n  File "C:\\Users\\Ian\\anaconda3\\envs\\qlbt\\lib\\concurrent\\futures\\_base.py", line 437, in result\n    return self.__get_result()\n  File "C:\\Users\\Ian\\anaconda3\\envs\\qlbt\\lib\\concurrent\\futures\\_base.py", line 389, in __get_result\n    raise self._exception\n  File "C:\\Users\\Ian\\Documents\\Financial testing\\data_pulling\\dump_bin.py", line 500, in _dump_features\n    _future.result()\n  File "C:\\Users\\Ian\\anaconda3\\envs\\qlbt\\lib\\concurrent\\futures\\_base.py", line 437, in result\n    return self.__get_result()\n  File "C:\\Users\\Ian\\anaconda3\\envs\\qlbt\\lib\\concurrent\\futures\\_base.py", line 389, in __get_result\n    raise self._exception\n  File "C:\\Users\\Ian\\Documents\\Financial testing\\data_pulling\\dump_bin.py", line 500, in _dump_features\n    _future.result()\n  File "C:\\Users\\Ian\\anaconda3\\envs\\qlbt\\lib\\concurrent\\futures\\_base.py", line 437, in result\n    return self.__get_result()\n  File "C:\\Users\\Ian\\anaconda3\\envs\\qlbt\\lib\\concurrent\\futures\\_base.py", line 389, in __get_result\n    raise self._exception\nconcurrent.futures.process.BrokenProcessPool: A process in the process pool was terminated abruptly while the future was running or pending.\n', 'ETHBUSD': 'Traceback (most recent call last):\n  File "C:\\Users\\Ian\\Documents\\Financial testing\\data_pulling\\dump_bin.py", line 500, in _dump_features\n    _future.result()\n  File "C:\\Users\\Ian\\anaconda3\\envs\\qlbt\\lib\\concurrent\\futures\\_base.py", line 437, in result\n    return self.__get_result()\n  File "C:\\Users\\Ian\\anaconda3\\envs\\qlbt\\lib\\concurrent\\futures\\_base.py", line 389, in __get_result\n    raise self._exception\n  File "C:\\Users\\Ian\\Documents\\Financial testing\\data_pulling\\dump_bin.py", line 500, in _dump_features\n    _future.result()\n  File "C:\\Users\\Ian\\anaconda3\\envs\\qlbt\\lib\\concurrent\\futures\\_base.py", line 437, in result\n    return self.__get_result()\n  File "C:\\Users\\Ian\\anaconda3\\envs\\qlbt\\lib\\concurrent\\futures\\_base.py", line 389, in __get_result\n    raise self._exception\n  File "C:\\Users\\Ian\\Documents\\Financial testing\\data_pulling\\dump_bin.py", line 500, in _dump_features\n    _future.result()\n  File "C:\\Users\\Ian\\anaconda3\\envs\\qlbt\\lib\\concurrent\\futures\\_base.py", line 437, in result\n    return self.__get_result()\n  File "C:\\Users\\Ian\\anaconda3\\envs\\qlbt\\lib\\concurrent\\futures\\_base.py", line 389, in __get_result\n    raise self._exception\n  File "C:\\Users\\Ian\\Documents\\Financial testing\\data_pulling\\dump_bin.py", line 500, in _dump_features\n    _future.result()\n  File "C:\\Users\\Ian\\anaconda3\\envs\\qlbt\\lib\\concurrent\\futures\\_base.py", line 437, in result\n    return self.__get_result()\n  File "C:\\Users\\Ian\\anaconda3\\envs\\qlbt\\lib\\concurrent\\futures\\_base.py", line 389, in __get_result\n    raise self._exception\n  File "C:\\Users\\Ian\\Documents\\Financial testing\\data_pulling\\dump_bin.py", line 500, in _dump_features\n    _future.result()\n  File "C:\\Users\\Ian\\anaconda3\\envs\\qlbt\\lib\\concurrent\\futures\\_base.py", line 437, in result\n    return self.__get_result()\n  File "C:\\Users\\Ian\\anaconda3\\envs\\qlbt\\lib\\concurrent\\futures\\_base.py", line 389, in __get_result\n    raise self._exception\n  File "C:\\Users\\Ian\\Documents\\Financial testing\\data_pulling\\dump_bin.py", line 500, in _dump_features\n    _future.result()\n  File "C:\\Users\\Ian\\anaconda3\\envs\\qlbt\\lib\\concurrent\\futures\\_base.py", line 437, in result\n    return self.__get_result()\n  File "C:\\Users\\Ian\\anaconda3\\envs\\qlbt\\lib\\concurrent\\futures\\_base.py", line 389, in __get_result\n    raise self._exception\n  File "C:\\Users\\Ian\\Documents\\Financial testing\\data_pulling\\dump_bin.py", line 500, in _dump_features\n    _future.result()\n  File "C:\\Users\\Ian\\anaconda3\\envs\\qlbt\\lib\\concurrent\\futures\\_base.py", line 437, in result\n    return self.__get_result()\n  File "C:\\Users\\Ian\\anaconda3\\envs\\qlbt\\lib\\concurrent\\futures\\_base.py", line 389, in __get_result\n    raise self._exception\n  File "C:\\Users\\Ian\\Documents\\Financial testing\\data_pulling\\dump_bin.py", line 500, in _dump_features\n    _future.result()\n  File "C:\\Users\\Ian\\anaconda3\\envs\\qlbt\\lib\\concurrent\\futures\\_base.py", line 437, in result\n    return self.__get_result()\n  File "C:\\Users\\Ian\\anaconda3\\envs\\qlbt\\lib\\concurrent\\futures\\_base.py", line 389, in __get_result\n    raise self._exception\n  File "C:\\Users\\Ian\\Documents\\Financial testing\\data_pulling\\dump_bin.py", line 500, in _dump_features\n    _future.result()\n  File "C:\\Users\\Ian\\anaconda3\\envs\\qlbt\\lib\\concurrent\\futures\\_base.py", line 437, in result\n    return self.__get_result()\n  File "C:\\Users\\Ian\\anaconda3\\envs\\qlbt\\lib\\concurrent\\futures\\_base.py", line 389, in __get_result\n    raise self._exception\nconcurrent.futures.process.BrokenProcessPool: A process in the process pool was terminated abruptly while the future was running or pending.\n', 'FTMBUSD': 'Traceback (most recent call last):\n  File "C:\\Users\\Ian\\Documents\\Financial testing\\data_pulling\\dump_bin.py", line 500, in _dump_features\n    _future.result()\n  File "C:\\Users\\Ian\\anaconda3\\envs\\qlbt\\lib\\concurrent\\futures\\_base.py", line 437, in result\n    return self.__get_result()\n  File "C:\\Users\\Ian\\anaconda3\\envs\\qlbt\\lib\\concurrent\\futures\\_base.py", line 389, in __get_result\n    raise self._exception\n  File "C:\\Users\\Ian\\Documents\\Financial testing\\data_pulling\\dump_bin.py", line 500, in _dump_features\n    _future.result()\n  File "C:\\Users\\Ian\\anaconda3\\envs\\qlbt\\lib\\concurrent\\futures\\_base.py", line 437, in result\n    return self.__get_result()\n  File "C:\\Users\\Ian\\anaconda3\\envs\\qlbt\\lib\\concurrent\\futures\\_base.py", line 389, in __get_result\n    raise self._exception\n  File "C:\\Users\\Ian\\Documents\\Financial testing\\data_pulling\\dump_bin.py", line 500, in _dump_features\n    _future.result()\n  File "C:\\Users\\Ian\\anaconda3\\envs\\qlbt\\lib\\concurrent\\futures\\_base.py", line 437, in result\n    return self.__get_result()\n  File "C:\\Users\\Ian\\anaconda3\\envs\\qlbt\\lib\\concurrent\\futures\\_base.py", line 389, in __get_result\n    raise self._exception\n  File "C:\\Users\\Ian\\Documents\\Financial testing\\data_pulling\\dump_bin.py", line 500, in _dump_features\n    _future.result()\n  File "C:\\Users\\Ian\\anaconda3\\envs\\qlbt\\lib\\concurrent\\futures\\_base.py", line 437, in result\n    return self.__get_result()\n  File "C:\\Users\\Ian\\anaconda3\\envs\\qlbt\\lib\\concurrent\\futures\\_base.py", line 389, in __get_result\n    raise self._exception\n  File "C:\\Users\\Ian\\Documents\\Financial testing\\data_pulling\\dump_bin.py", line 500, in _dump_features\n    _future.result()\n  File "C:\\Users\\Ian\\anaconda3\\envs\\qlbt\\lib\\concurrent\\futures\\_base.py", line 437, in result\n    return self.__get_result()\n  File "C:\\Users\\Ian\\anaconda3\\envs\\qlbt\\lib\\concurrent\\futures\\_base.py", line 389, in __get_result\n    raise self._exception\n  File "C:\\Users\\Ian\\Documents\\Financial testing\\data_pulling\\dump_bin.py", line 500, in _dump_features\n    _future.result()\n  File "C:\\Users\\Ian\\anaconda3\\envs\\qlbt\\lib\\concurrent\\futures\\_base.py", line 437, in result\n    return self.__get_result()\n  File "C:\\Users\\Ian\\anaconda3\\envs\\qlbt\\lib\\concurrent\\futures\\_base.py", line 389, in __get_result\n    raise self._exception\n  File "C:\\Users\\Ian\\Documents\\Financial testing\\data_pulling\\dump_bin.py", line 500, in _dump_features\n    _future.result()\n  File "C:\\Users\\Ian\\anaconda3\\envs\\qlbt\\lib\\concurrent\\futures\\_base.py", line 437, in result\n    return self.__get_result()\n  File "C:\\Users\\Ian\\anaconda3\\envs\\qlbt\\lib\\concurrent\\futures\\_base.py", line 389, in __get_result\n    raise self._exception\n  File "C:\\Users\\Ian\\Documents\\Financial testing\\data_pulling\\dump_bin.py", line 500, in _dump_features\n    _future.result()\n  File "C:\\Users\\Ian\\anaconda3\\envs\\qlbt\\lib\\concurrent\\futures\\_base.py", line 437, in result\n    return self.__get_result()\n  File "C:\\Users\\Ian\\anaconda3\\envs\\qlbt\\lib\\concurrent\\futures\\_base.py", line 389, in __get_result\n    raise self._exception\n  File "C:\\Users\\Ian\\Documents\\Financial testing\\data_pulling\\dump_bin.py", line 500, in _dump_features\n    _future.result()\n  File "C:\\Users\\Ian\\anaconda3\\envs\\qlbt\\lib\\concurrent\\futures\\_base.py", line 437, in result\n    return self.__get_result()\n  File "C:\\Users\\Ian\\anaconda3\\envs\\qlbt\\lib\\concurrent\\futures\\_base.py", line 389, in __get_result\n    raise self._exception\n  File "C:\\Users\\Ian\\Documents\\Financial testing\\data_pulling\\dump_bin.py", line 500, in _dump_features\n    _future.result()\n  File "C:\\Users\\Ian\\anaconda3\\envs\\qlbt\\lib\\concurrent\\futures\\_base.py", line 437, in result\n    return self.__get_result()\n  File "C:\\Users\\Ian\\anaconda3\\envs\\qlbt\\lib\\concurrent\\futures\\_base.py", line 389, in __get_result\n    raise self._exception\nconcurrent.futures.process.BrokenProcessPool: A process in the process pool was terminated abruptly while the future was running or pending.\n', 'ICPBUSD': 'Traceback (most recent call last):\n  File "C:\\Users\\Ian\\Documents\\Financial testing\\data_pulling\\dump_bin.py", line 500, in _dump_features\n    _future.result()\n  File "C:\\Users\\Ian\\anaconda3\\envs\\qlbt\\lib\\concurrent\\futures\\_base.py", line 437, in result\n    return self.__get_result()\n  File "C:\\Users\\Ian\\anaconda3\\envs\\qlbt\\lib\\concurrent\\futures\\_base.py", line 389, in __get_result\n    raise self._exception\n  File "C:\\Users\\Ian\\Documents\\Financial testing\\data_pulling\\dump_bin.py", line 500, in _dump_features\n    _future.result()\n  File "C:\\Users\\Ian\\anaconda3\\envs\\qlbt\\lib\\concurrent\\futures\\_base.py", line 437, in result\n    return self.__get_result()\n  File "C:\\Users\\Ian\\anaconda3\\envs\\qlbt\\lib\\concurrent\\futures\\_base.py", line 389, in __get_result\n    raise self._exception\n  File "C:\\Users\\Ian\\Documents\\Financial testing\\data_pulling\\dump_bin.py", line 500, in _dump_features\n    _future.result()\n  File "C:\\Users\\Ian\\anaconda3\\envs\\qlbt\\lib\\concurrent\\futures\\_base.py", line 437, in result\n    return self.__get_result()\n  File "C:\\Users\\Ian\\anaconda3\\envs\\qlbt\\lib\\concurrent\\futures\\_base.py", line 389, in __get_result\n    raise self._exception\n  File "C:\\Users\\Ian\\Documents\\Financial testing\\data_pulling\\dump_bin.py", line 500, in _dump_features\n    _future.result()\n  File "C:\\Users\\Ian\\anaconda3\\envs\\qlbt\\lib\\concurrent\\futures\\_base.py", line 437, in result\n    return self.__get_result()\n  File "C:\\Users\\Ian\\anaconda3\\envs\\qlbt\\lib\\concurrent\\futures\\_base.py", line 389, in __get_result\n    raise self._exception\n  File "C:\\Users\\Ian\\Documents\\Financial testing\\data_pulling\\dump_bin.py", line 500, in _dump_features\n    _future.result()\n  File "C:\\Users\\Ian\\anaconda3\\envs\\qlbt\\lib\\concurrent\\futures\\_base.py", line 437, in result\n    return self.__get_result()\n  File "C:\\Users\\Ian\\anaconda3\\envs\\qlbt\\lib\\concurrent\\futures\\_base.py", line 389, in __get_result\n    raise self._exception\n  File "C:\\Users\\Ian\\Documents\\Financial testing\\data_pulling\\dump_bin.py", line 500, in _dump_features\n    _future.result()\n  File "C:\\Users\\Ian\\anaconda3\\envs\\qlbt\\lib\\concurrent\\futures\\_base.py", line 437, in result\n    return self.__get_result()\n  File "C:\\Users\\Ian\\anaconda3\\envs\\qlbt\\lib\\concurrent\\futures\\_base.py", line 389, in __get_result\n    raise self._exception\n  File "C:\\Users\\Ian\\Documents\\Financial testing\\data_pulling\\dump_bin.py", line 500, in _dump_features\n    _future.result()\n  File "C:\\Users\\Ian\\anaconda3\\envs\\qlbt\\lib\\concurrent\\futures\\_base.py", line 437, in result\n    return self.__get_result()\n  File "C:\\Users\\Ian\\anaconda3\\envs\\qlbt\\lib\\concurrent\\futures\\_base.py", line 389, in __get_result\n    raise self._exception\n  File "C:\\Users\\Ian\\Documents\\Financial testing\\data_pulling\\dump_bin.py", line 500, in _dump_features\n    _future.result()\n  File "C:\\Users\\Ian\\anaconda3\\envs\\qlbt\\lib\\concurrent\\futures\\_base.py", line 437, in result\n    return self.__get_result()\n  File "C:\\Users\\Ian\\anaconda3\\envs\\qlbt\\lib\\concurrent\\futures\\_base.py", line 389, in __get_result\n    raise self._exception\n  File "C:\\Users\\Ian\\Documents\\Financial testing\\data_pulling\\dump_bin.py", line 500, in _dump_features\n    _future.result()\n  File "C:\\Users\\Ian\\anaconda3\\envs\\qlbt\\lib\\concurrent\\futures\\_base.py", line 437, in result\n    return self.__get_result()\n  File "C:\\Users\\Ian\\anaconda3\\envs\\qlbt\\lib\\concurrent\\futures\\_base.py", line 389, in __get_result\n    raise self._exception\n  File "C:\\Users\\Ian\\Documents\\Financial testing\\data_pulling\\dump_bin.py", line 500, in _dump_features\n    _future.result()\n  File "C:\\Users\\Ian\\anaconda3\\envs\\qlbt\\lib\\concurrent\\futures\\_base.py", line 437, in result\n    return self.__get_result()\n  File "C:\\Users\\Ian\\anaconda3\\envs\\qlbt\\lib\\concurrent\\futures\\_base.py", line 389, in __get_result\n    raise self._exception\n  File "C:\\Users\\Ian\\Documents\\Financial testing\\data_pulling\\dump_bin.py", line 500, in _dump_features\n    _future.result()\n  File "C:\\Users\\Ian\\anaconda3\\envs\\qlbt\\lib\\concurrent\\futures\\_base.py", line 437, in result\n    return self.__get_result()\n  File "C:\\Users\\Ian\\anaconda3\\envs\\qlbt\\lib\\concurrent\\futures\\_base.py", line 389, in __get_result\n    raise self._exception\nconcurrent.futures.process.BrokenProcessPool: A process in the process pool was terminated abruptly while the future was running or pending.\n', 'MATICBUSD': 'Traceback (most recent call last):\n  File "C:\\Users\\Ian\\Documents\\Financial testing\\data_pulling\\dump_bin.py", line 500, in _dump_features\n    _future.result()\n  File "C:\\Users\\Ian\\anaconda3\\envs\\qlbt\\lib\\concurrent\\futures\\_base.py", line 437, in result\n    return self.__get_result()\n  File "C:\\Users\\Ian\\anaconda3\\envs\\qlbt\\lib\\concurrent\\futures\\_base.py", line 389, in __get_result\n    raise self._exception\n  File "C:\\Users\\Ian\\Documents\\Financial testing\\data_pulling\\dump_bin.py", line 500, in _dump_features\n    _future.result()\n  File "C:\\Users\\Ian\\anaconda3\\envs\\qlbt\\lib\\concurrent\\futures\\_base.py", line 437, in result\n    return self.__get_result()\n  File "C:\\Users\\Ian\\anaconda3\\envs\\qlbt\\lib\\concurrent\\futures\\_base.py", line 389, in __get_result\n    raise self._exception\n  File "C:\\Users\\Ian\\Documents\\Financial testing\\data_pulling\\dump_bin.py", line 500, in _dump_features\n    _future.result()\n  File "C:\\Users\\Ian\\anaconda3\\envs\\qlbt\\lib\\concurrent\\futures\\_base.py", line 437, in result\n    return self.__get_result()\n  File "C:\\Users\\Ian\\anaconda3\\envs\\qlbt\\lib\\concurrent\\futures\\_base.py", line 389, in __get_result\n    raise self._exception\n  File "C:\\Users\\Ian\\Documents\\Financial testing\\data_pulling\\dump_bin.py", line 500, in _dump_features\n    _future.result()\n  File "C:\\Users\\Ian\\anaconda3\\envs\\qlbt\\lib\\concurrent\\futures\\_base.py", line 437, in result\n    return self.__get_result()\n  File "C:\\Users\\Ian\\anaconda3\\envs\\qlbt\\lib\\concurrent\\futures\\_base.py", line 389, in __get_result\n    raise self._exception\n  File "C:\\Users\\Ian\\Documents\\Financial testing\\data_pulling\\dump_bin.py", line 500, in _dump_features\n    _future.result()\n  File "C:\\Users\\Ian\\anaconda3\\envs\\qlbt\\lib\\concurrent\\futures\\_base.py", line 437, in result\n    return self.__get_result()\n  File "C:\\Users\\Ian\\anaconda3\\envs\\qlbt\\lib\\concurrent\\futures\\_base.py", line 389, in __get_result\n    raise self._exception\n  File "C:\\Users\\Ian\\Documents\\Financial testing\\data_pulling\\dump_bin.py", line 500, in _dump_features\n    _future.result()\n  File "C:\\Users\\Ian\\anaconda3\\envs\\qlbt\\lib\\concurrent\\futures\\_base.py", line 437, in result\n    return self.__get_result()\n  File "C:\\Users\\Ian\\anaconda3\\envs\\qlbt\\lib\\concurrent\\futures\\_base.py", line 389, in __get_result\n    raise self._exception\n  File "C:\\Users\\Ian\\Documents\\Financial testing\\data_pulling\\dump_bin.py", line 500, in _dump_features\n    _future.result()\n  File "C:\\Users\\Ian\\anaconda3\\envs\\qlbt\\lib\\concurrent\\futures\\_base.py", line 437, in result\n    return self.__get_result()\n  File "C:\\Users\\Ian\\anaconda3\\envs\\qlbt\\lib\\concurrent\\futures\\_base.py", line 389, in __get_result\n    raise self._exception\n  File "C:\\Users\\Ian\\Documents\\Financial testing\\data_pulling\\dump_bin.py", line 500, in _dump_features\n    _future.result()\n  File "C:\\Users\\Ian\\anaconda3\\envs\\qlbt\\lib\\concurrent\\futures\\_base.py", line 437, in result\n    return self.__get_result()\n  File "C:\\Users\\Ian\\anaconda3\\envs\\qlbt\\lib\\concurrent\\futures\\_base.py", line 389, in __get_result\n    raise self._exception\n  File "C:\\Users\\Ian\\Documents\\Financial testing\\data_pulling\\dump_bin.py", line 500, in _dump_features\n    _future.result()\n  File "C:\\Users\\Ian\\anaconda3\\envs\\qlbt\\lib\\concurrent\\futures\\_base.py", line 437, in result\n    return self.__get_result()\n  File "C:\\Users\\Ian\\anaconda3\\envs\\qlbt\\lib\\concurrent\\futures\\_base.py", line 389, in __get_result\n    raise self._exception\n  File "C:\\Users\\Ian\\Documents\\Financial testing\\data_pulling\\dump_bin.py", line 500, in _dump_features\n    _future.result()\n  File "C:\\Users\\Ian\\anaconda3\\envs\\qlbt\\lib\\concurrent\\futures\\_base.py", line 437, in result\n    return self.__get_result()\n  File "C:\\Users\\Ian\\anaconda3\\envs\\qlbt\\lib\\concurrent\\futures\\_base.py", line 389, in __get_result\n    raise self._exception\n  File "C:\\Users\\Ian\\Documents\\Financial testing\\data_pulling\\dump_bin.py", line 500, in _dump_features\n    _future.result()\n  File "C:\\Users\\Ian\\anaconda3\\envs\\qlbt\\lib\\concurrent\\futures\\_base.py", line 437, in result\n    return self.__get_result()\n  File "C:\\Users\\Ian\\anaconda3\\envs\\qlbt\\lib\\concurrent\\futures\\_base.py", line 389, in __get_result\n    raise self._exception\n  File "C:\\Users\\Ian\\Documents\\Financial testing\\data_pulling\\dump_bin.py", line 500, in _dump_features\n    _future.result()\n  File "C:\\Users\\Ian\\anaconda3\\envs\\qlbt\\lib\\concurrent\\futures\\_base.py", line 437, in result\n    return self.__get_result()\n  File "C:\\Users\\Ian\\anaconda3\\envs\\qlbt\\lib\\concurrent\\futures\\_base.py", line 389, in __get_result\n    raise self._exception\nconcurrent.futures.process.BrokenProcessPool: A process in the process pool was terminated abruptly while the future was running or pending.\n', 'NEARBUSD': 'Traceback (most recent call last):\n  File "C:\\Users\\Ian\\Documents\\Financial testing\\data_pulling\\dump_bin.py", line 500, in _dump_features\n    _future.result()\n  File "C:\\Users\\Ian\\anaconda3\\envs\\qlbt\\lib\\concurrent\\futures\\_base.py", line 437, in result\n    return self.__get_result()\n  File "C:\\Users\\Ian\\anaconda3\\envs\\qlbt\\lib\\concurrent\\futures\\_base.py", line 389, in __get_result\n    raise self._exception\n  File "C:\\Users\\Ian\\Documents\\Financial testing\\data_pulling\\dump_bin.py", line 500, in _dump_features\n    _future.result()\n  File "C:\\Users\\Ian\\anaconda3\\envs\\qlbt\\lib\\concurrent\\futures\\_base.py", line 437, in result\n    return self.__get_result()\n  File "C:\\Users\\Ian\\anaconda3\\envs\\qlbt\\lib\\concurrent\\futures\\_base.py", line 389, in __get_result\n    raise self._exception\n  File "C:\\Users\\Ian\\Documents\\Financial testing\\data_pulling\\dump_bin.py", line 500, in _dump_features\n    _future.result()\n  File "C:\\Users\\Ian\\anaconda3\\envs\\qlbt\\lib\\concurrent\\futures\\_base.py", line 437, in result\n    return self.__get_result()\n  File "C:\\Users\\Ian\\anaconda3\\envs\\qlbt\\lib\\concurrent\\futures\\_base.py", line 389, in __get_result\n    raise self._exception\n  File "C:\\Users\\Ian\\Documents\\Financial testing\\data_pulling\\dump_bin.py", line 500, in _dump_features\n    _future.result()\n  File "C:\\Users\\Ian\\anaconda3\\envs\\qlbt\\lib\\concurrent\\futures\\_base.py", line 437, in result\n    return self.__get_result()\n  File "C:\\Users\\Ian\\anaconda3\\envs\\qlbt\\lib\\concurrent\\futures\\_base.py", line 389, in __get_result\n    raise self._exception\n  File "C:\\Users\\Ian\\Documents\\Financial testing\\data_pulling\\dump_bin.py", line 500, in _dump_features\n    _future.result()\n  File "C:\\Users\\Ian\\anaconda3\\envs\\qlbt\\lib\\concurrent\\futures\\_base.py", line 437, in result\n    return self.__get_result()\n  File "C:\\Users\\Ian\\anaconda3\\envs\\qlbt\\lib\\concurrent\\futures\\_base.py", line 389, in __get_result\n    raise self._exception\n  File "C:\\Users\\Ian\\Documents\\Financial testing\\data_pulling\\dump_bin.py", line 500, in _dump_features\n    _future.result()\n  File "C:\\Users\\Ian\\anaconda3\\envs\\qlbt\\lib\\concurrent\\futures\\_base.py", line 437, in result\n    return self.__get_result()\n  File "C:\\Users\\Ian\\anaconda3\\envs\\qlbt\\lib\\concurrent\\futures\\_base.py", line 389, in __get_result\n    raise self._exception\n  File "C:\\Users\\Ian\\Documents\\Financial testing\\data_pulling\\dump_bin.py", line 500, in _dump_features\n    _future.result()\n  File "C:\\Users\\Ian\\anaconda3\\envs\\qlbt\\lib\\concurrent\\futures\\_base.py", line 437, in result\n    return self.__get_result()\n  File "C:\\Users\\Ian\\anaconda3\\envs\\qlbt\\lib\\concurrent\\futures\\_base.py", line 389, in __get_result\n    raise self._exception\n  File "C:\\Users\\Ian\\Documents\\Financial testing\\data_pulling\\dump_bin.py", line 500, in _dump_features\n    _future.result()\n  File "C:\\Users\\Ian\\anaconda3\\envs\\qlbt\\lib\\concurrent\\futures\\_base.py", line 437, in result\n    return self.__get_result()\n  File "C:\\Users\\Ian\\anaconda3\\envs\\qlbt\\lib\\concurrent\\futures\\_base.py", line 389, in __get_result\n    raise self._exception\n  File "C:\\Users\\Ian\\Documents\\Financial testing\\data_pulling\\dump_bin.py", line 500, in _dump_features\n    _future.result()\n  File "C:\\Users\\Ian\\anaconda3\\envs\\qlbt\\lib\\concurrent\\futures\\_base.py", line 437, in result\n    return self.__get_result()\n  File "C:\\Users\\Ian\\anaconda3\\envs\\qlbt\\lib\\concurrent\\futures\\_base.py", line 389, in __get_result\n    raise self._exception\n  File "C:\\Users\\Ian\\Documents\\Financial testing\\data_pulling\\dump_bin.py", line 500, in _dump_features\n    _future.result()\n  File "C:\\Users\\Ian\\anaconda3\\envs\\qlbt\\lib\\concurrent\\futures\\_base.py", line 437, in result\n    return self.__get_result()\n  File "C:\\Users\\Ian\\anaconda3\\envs\\qlbt\\lib\\concurrent\\futures\\_base.py", line 389, in __get_result\n    raise self._exception\n  File "C:\\Users\\Ian\\Documents\\Financial testing\\data_pulling\\dump_bin.py", line 500, in _dump_features\n    _future.result()\n  File "C:\\Users\\Ian\\anaconda3\\envs\\qlbt\\lib\\concurrent\\futures\\_base.py", line 437, in result\n    return self.__get_result()\n  File "C:\\Users\\Ian\\anaconda3\\envs\\qlbt\\lib\\concurrent\\futures\\_base.py", line 389, in __get_result\n    raise self._exception\n  File "C:\\Users\\Ian\\Documents\\Financial testing\\data_pulling\\dump_bin.py", line 500, in _dump_features\n    _future.result()\n  File "C:\\Users\\Ian\\anaconda3\\envs\\qlbt\\lib\\concurrent\\futures\\_base.py", line 437, in result\n    return self.__get_result()\n  File "C:\\Users\\Ian\\anaconda3\\envs\\qlbt\\lib\\concurrent\\futures\\_base.py", line 389, in __get_result\n    raise self._exception\n  File "C:\\Users\\Ian\\Documents\\Financial testing\\data_pulling\\dump_bin.py", line 500, in _dump_features\n    _future.result()\n  File "C:\\Users\\Ian\\anaconda3\\envs\\qlbt\\lib\\concurrent\\futures\\_base.py", line 437, in result\n    return self.__get_result()\n  File "C:\\Users\\Ian\\anaconda3\\envs\\qlbt\\lib\\concurrent\\futures\\_base.py", line 389, in __get_result\n    raise self._exception\nconcurrent.futures.process.BrokenProcessPool: A process in the process pool was terminated abruptly while the future was running or pending.\n', 'OPBUSD': 'Traceback (most recent call last):\n  File "C:\\Users\\Ian\\Documents\\Financial testing\\data_pulling\\dump_bin.py", line 500, in _dump_features\n    _future.result()\n  File "C:\\Users\\Ian\\anaconda3\\envs\\qlbt\\lib\\concurrent\\futures\\_base.py", line 437, in result\n    return self.__get_result()\n  File "C:\\Users\\Ian\\anaconda3\\envs\\qlbt\\lib\\concurrent\\futures\\_base.py", line 389, in __get_result\n    raise self._exception\n  File "C:\\Users\\Ian\\Documents\\Financial testing\\data_pulling\\dump_bin.py", line 500, in _dump_features\n    _future.result()\n  File "C:\\Users\\Ian\\anaconda3\\envs\\qlbt\\lib\\concurrent\\futures\\_base.py", line 437, in result\n    return self.__get_result()\n  File "C:\\Users\\Ian\\anaconda3\\envs\\qlbt\\lib\\concurrent\\futures\\_base.py", line 389, in __get_result\n    raise self._exception\n  File "C:\\Users\\Ian\\Documents\\Financial testing\\data_pulling\\dump_bin.py", line 500, in _dump_features\n    _future.result()\n  File "C:\\Users\\Ian\\anaconda3\\envs\\qlbt\\lib\\concurrent\\futures\\_base.py", line 437, in result\n    return self.__get_result()\n  File "C:\\Users\\Ian\\anaconda3\\envs\\qlbt\\lib\\concurrent\\futures\\_base.py", line 389, in __get_result\n    raise self._exception\n  File "C:\\Users\\Ian\\Documents\\Financial testing\\data_pulling\\dump_bin.py", line 500, in _dump_features\n    _future.result()\n  File "C:\\Users\\Ian\\anaconda3\\envs\\qlbt\\lib\\concurrent\\futures\\_base.py", line 437, in result\n    return self.__get_result()\n  File "C:\\Users\\Ian\\anaconda3\\envs\\qlbt\\lib\\concurrent\\futures\\_base.py", line 389, in __get_result\n    raise self._exception\n  File "C:\\Users\\Ian\\Documents\\Financial testing\\data_pulling\\dump_bin.py", line 500, in _dump_features\n    _future.result()\n  File "C:\\Users\\Ian\\anaconda3\\envs\\qlbt\\lib\\concurrent\\futures\\_base.py", line 437, in result\n    return self.__get_result()\n  File "C:\\Users\\Ian\\anaconda3\\envs\\qlbt\\lib\\concurrent\\futures\\_base.py", line 389, in __get_result\n    raise self._exception\n  File "C:\\Users\\Ian\\Documents\\Financial testing\\data_pulling\\dump_bin.py", line 500, in _dump_features\n    _future.result()\n  File "C:\\Users\\Ian\\anaconda3\\envs\\qlbt\\lib\\concurrent\\futures\\_base.py", line 437, in result\n    return self.__get_result()\n  File "C:\\Users\\Ian\\anaconda3\\envs\\qlbt\\lib\\concurrent\\futures\\_base.py", line 389, in __get_result\n    raise self._exception\n  File "C:\\Users\\Ian\\Documents\\Financial testing\\data_pulling\\dump_bin.py", line 500, in _dump_features\n    _future.result()\n  File "C:\\Users\\Ian\\anaconda3\\envs\\qlbt\\lib\\concurrent\\futures\\_base.py", line 437, in result\n    return self.__get_result()\n  File "C:\\Users\\Ian\\anaconda3\\envs\\qlbt\\lib\\concurrent\\futures\\_base.py", line 389, in __get_result\n    raise self._exception\n  File "C:\\Users\\Ian\\Documents\\Financial testing\\data_pulling\\dump_bin.py", line 500, in _dump_features\n    _future.result()\n  File "C:\\Users\\Ian\\anaconda3\\envs\\qlbt\\lib\\concurrent\\futures\\_base.py", line 437, in result\n    return self.__get_result()\n  File "C:\\Users\\Ian\\anaconda3\\envs\\qlbt\\lib\\concurrent\\futures\\_base.py", line 389, in __get_result\n    raise self._exception\n  File "C:\\Users\\Ian\\Documents\\Financial testing\\data_pulling\\dump_bin.py", line 500, in _dump_features\n    _future.result()\n  File "C:\\Users\\Ian\\anaconda3\\envs\\qlbt\\lib\\concurrent\\futures\\_base.py", line 437, in result\n    return self.__get_result()\n  File "C:\\Users\\Ian\\anaconda3\\envs\\qlbt\\lib\\concurrent\\futures\\_base.py", line 389, in __get_result\n    raise self._exception\n  File "C:\\Users\\Ian\\Documents\\Financial testing\\data_pulling\\dump_bin.py", line 500, in _dump_features\n    _future.result()\n  File "C:\\Users\\Ian\\anaconda3\\envs\\qlbt\\lib\\concurrent\\futures\\_base.py", line 437, in result\n    return self.__get_result()\n  File "C:\\Users\\Ian\\anaconda3\\envs\\qlbt\\lib\\concurrent\\futures\\_base.py", line 389, in __get_result\n    raise self._exception\n  File "C:\\Users\\Ian\\Documents\\Financial testing\\data_pulling\\dump_bin.py", line 500, in _dump_features\n    _future.result()\n  File "C:\\Users\\Ian\\anaconda3\\envs\\qlbt\\lib\\concurrent\\futures\\_base.py", line 437, in result\n    return self.__get_result()\n  File "C:\\Users\\Ian\\anaconda3\\envs\\qlbt\\lib\\concurrent\\futures\\_base.py", line 389, in __get_result\n    raise self._exception\n  File "C:\\Users\\Ian\\Documents\\Financial testing\\data_pulling\\dump_bin.py", line 500, in _dump_features\n    _future.result()\n  File "C:\\Users\\Ian\\anaconda3\\envs\\qlbt\\lib\\concurrent\\futures\\_base.py", line 437, in result\n    return self.__get_result()\n  File "C:\\Users\\Ian\\anaconda3\\envs\\qlbt\\lib\\concurrent\\futures\\_base.py", line 389, in __get_result\n    raise self._exception\n  File "C:\\Users\\Ian\\Documents\\Financial testing\\data_pulling\\dump_bin.py", line 500, in _dump_features\n    _future.result()\n  File "C:\\Users\\Ian\\anaconda3\\envs\\qlbt\\lib\\concurrent\\futures\\_base.py", line 437, in result\n    return self.__get_result()\n  File "C:\\Users\\Ian\\anaconda3\\envs\\qlbt\\lib\\concurrent\\futures\\_base.py", line 389, in __get_result\n    raise self._exception\n  File "C:\\Users\\Ian\\Documents\\Financial testing\\data_pulling\\dump_bin.py", line 500, in _dump_features\n    _future.result()\n  File "C:\\Users\\Ian\\anaconda3\\envs\\qlbt\\lib\\concurrent\\futures\\_base.py", line 437, in result\n    return self.__get_result()\n  File "C:\\Users\\Ian\\anaconda3\\envs\\qlbt\\lib\\concurrent\\futures\\_base.py", line 389, in __get_result\n    raise self._exception\nconcurrent.futures.process.BrokenProcessPool: A process in the process pool was terminated abruptly while the future was running or pending.\n', 'SOLBUSD': 'Traceback (most recent call last):\n  File "C:\\Users\\Ian\\Documents\\Financial testing\\data_pulling\\dump_bin.py", line 500, in _dump_features\n    _future.result()\n  File "C:\\Users\\Ian\\anaconda3\\envs\\qlbt\\lib\\concurrent\\futures\\_base.py", line 437, in result\n    return self.__get_result()\n  File "C:\\Users\\Ian\\anaconda3\\envs\\qlbt\\lib\\concurrent\\futures\\_base.py", line 389, in __get_result\n    raise self._exception\n  File "C:\\Users\\Ian\\Documents\\Financial testing\\data_pulling\\dump_bin.py", line 500, in _dump_features\n    _future.result()\n  File "C:\\Users\\Ian\\anaconda3\\envs\\qlbt\\lib\\concurrent\\futures\\_base.py", line 437, in result\n    return self.__get_result()\n  File "C:\\Users\\Ian\\anaconda3\\envs\\qlbt\\lib\\concurrent\\futures\\_base.py", line 389, in __get_result\n    raise self._exception\n  File "C:\\Users\\Ian\\Documents\\Financial testing\\data_pulling\\dump_bin.py", line 500, in _dump_features\n    _future.result()\n  File "C:\\Users\\Ian\\anaconda3\\envs\\qlbt\\lib\\concurrent\\futures\\_base.py", line 437, in result\n    return self.__get_result()\n  File "C:\\Users\\Ian\\anaconda3\\envs\\qlbt\\lib\\concurrent\\futures\\_base.py", line 389, in __get_result\n    raise self._exception\n  File "C:\\Users\\Ian\\Documents\\Financial testing\\data_pulling\\dump_bin.py", line 500, in _dump_features\n    _future.result()\n  File "C:\\Users\\Ian\\anaconda3\\envs\\qlbt\\lib\\concurrent\\futures\\_base.py", line 437, in result\n    return self.__get_result()\n  File "C:\\Users\\Ian\\anaconda3\\envs\\qlbt\\lib\\concurrent\\futures\\_base.py", line 389, in __get_result\n    raise self._exception\n  File "C:\\Users\\Ian\\Documents\\Financial testing\\data_pulling\\dump_bin.py", line 500, in _dump_features\n    _future.result()\n  File "C:\\Users\\Ian\\anaconda3\\envs\\qlbt\\lib\\concurrent\\futures\\_base.py", line 437, in result\n    return self.__get_result()\n  File "C:\\Users\\Ian\\anaconda3\\envs\\qlbt\\lib\\concurrent\\futures\\_base.py", line 389, in __get_result\n    raise self._exception\n  File "C:\\Users\\Ian\\Documents\\Financial testing\\data_pulling\\dump_bin.py", line 500, in _dump_features\n    _future.result()\n  File "C:\\Users\\Ian\\anaconda3\\envs\\qlbt\\lib\\concurrent\\futures\\_base.py", line 437, in result\n    return self.__get_result()\n  File "C:\\Users\\Ian\\anaconda3\\envs\\qlbt\\lib\\concurrent\\futures\\_base.py", line 389, in __get_result\n    raise self._exception\n  File "C:\\Users\\Ian\\Documents\\Financial testing\\data_pulling\\dump_bin.py", line 500, in _dump_features\n    _future.result()\n  File "C:\\Users\\Ian\\anaconda3\\envs\\qlbt\\lib\\concurrent\\futures\\_base.py", line 437, in result\n    return self.__get_result()\n  File "C:\\Users\\Ian\\anaconda3\\envs\\qlbt\\lib\\concurrent\\futures\\_base.py", line 389, in __get_result\n    raise self._exception\n  File "C:\\Users\\Ian\\Documents\\Financial testing\\data_pulling\\dump_bin.py", line 500, in _dump_features\n    _future.result()\n  File "C:\\Users\\Ian\\anaconda3\\envs\\qlbt\\lib\\concurrent\\futures\\_base.py", line 437, in result\n    return self.__get_result()\n  File "C:\\Users\\Ian\\anaconda3\\envs\\qlbt\\lib\\concurrent\\futures\\_base.py", line 389, in __get_result\n    raise self._exception\n  File "C:\\Users\\Ian\\Documents\\Financial testing\\data_pulling\\dump_bin.py", line 500, in _dump_features\n    _future.result()\n  File "C:\\Users\\Ian\\anaconda3\\envs\\qlbt\\lib\\concurrent\\futures\\_base.py", line 437, in result\n    return self.__get_result()\n  File "C:\\Users\\Ian\\anaconda3\\envs\\qlbt\\lib\\concurrent\\futures\\_base.py", line 389, in __get_result\n    raise self._exception\n  File "C:\\Users\\Ian\\Documents\\Financial testing\\data_pulling\\dump_bin.py", line 500, in _dump_features\n    _future.result()\n  File "C:\\Users\\Ian\\anaconda3\\envs\\qlbt\\lib\\concurrent\\futures\\_base.py", line 437, in result\n    return self.__get_result()\n  File "C:\\Users\\Ian\\anaconda3\\envs\\qlbt\\lib\\concurrent\\futures\\_base.py", line 389, in __get_result\n    raise self._exception\n  File "C:\\Users\\Ian\\Documents\\Financial testing\\data_pulling\\dump_bin.py", line 500, in _dump_features\n    _future.result()\n  File "C:\\Users\\Ian\\anaconda3\\envs\\qlbt\\lib\\concurrent\\futures\\_base.py", line 437, in result\n    return self.__get_result()\n  File "C:\\Users\\Ian\\anaconda3\\envs\\qlbt\\lib\\concurrent\\futures\\_base.py", line 389, in __get_result\n    raise self._exception\n  File "C:\\Users\\Ian\\Documents\\Financial testing\\data_pulling\\dump_bin.py", line 500, in _dump_features\n    _future.result()\n  File "C:\\Users\\Ian\\anaconda3\\envs\\qlbt\\lib\\concurrent\\futures\\_base.py", line 437, in result\n    return self.__get_result()\n  File "C:\\Users\\Ian\\anaconda3\\envs\\qlbt\\lib\\concurrent\\futures\\_base.py", line 389, in __get_result\n    raise self._exception\n  File "C:\\Users\\Ian\\Documents\\Financial testing\\data_pulling\\dump_bin.py", line 500, in _dump_features\n    _future.result()\n  File "C:\\Users\\Ian\\anaconda3\\envs\\qlbt\\lib\\concurrent\\futures\\_base.py", line 437, in result\n    return self.__get_result()\n  File "C:\\Users\\Ian\\anaconda3\\envs\\qlbt\\lib\\concurrent\\futures\\_base.py", line 389, in __get_result\n    raise self._exception\n  File "C:\\Users\\Ian\\Documents\\Financial testing\\data_pulling\\dump_bin.py", line 500, in _dump_features\n    _future.result()\n  File "C:\\Users\\Ian\\anaconda3\\envs\\qlbt\\lib\\concurrent\\futures\\_base.py", line 437, in result\n    return self.__get_result()\n  File "C:\\Users\\Ian\\anaconda3\\envs\\qlbt\\lib\\concurrent\\futures\\_base.py", line 389, in __get_result\n    raise self._exception\n  File "C:\\Users\\Ian\\Documents\\Financial testing\\data_pulling\\dump_bin.py", line 500, in _dump_features\n    _future.result()\n  File "C:\\Users\\Ian\\anaconda3\\envs\\qlbt\\lib\\concurrent\\futures\\_base.py", line 437, in result\n    return self.__get_result()\n  File "C:\\Users\\Ian\\anaconda3\\envs\\qlbt\\lib\\concurrent\\futures\\_base.py", line 389, in __get_result\n    raise self._exception\nconcurrent.futures.process.BrokenProcessPool: A process in the process pool was terminated abruptly while the future was running or pending.\n', 'TRXBUSD': 'Traceback (most recent call last):\n  File "C:\\Users\\Ian\\Documents\\Financial testing\\data_pulling\\dump_bin.py", line 500, in _dump_features\n    _future.result()\n  File "C:\\Users\\Ian\\anaconda3\\envs\\qlbt\\lib\\concurrent\\futures\\_base.py", line 437, in result\n    return self.__get_result()\n  File "C:\\Users\\Ian\\anaconda3\\envs\\qlbt\\lib\\concurrent\\futures\\_base.py", line 389, in __get_result\n    raise self._exception\n  File "C:\\Users\\Ian\\Documents\\Financial testing\\data_pulling\\dump_bin.py", line 500, in _dump_features\n    _future.result()\n  File "C:\\Users\\Ian\\anaconda3\\envs\\qlbt\\lib\\concurrent\\futures\\_base.py", line 437, in result\n    return self.__get_result()\n  File "C:\\Users\\Ian\\anaconda3\\envs\\qlbt\\lib\\concurrent\\futures\\_base.py", line 389, in __get_result\n    raise self._exception\n  File "C:\\Users\\Ian\\Documents\\Financial testing\\data_pulling\\dump_bin.py", line 500, in _dump_features\n    _future.result()\n  File "C:\\Users\\Ian\\anaconda3\\envs\\qlbt\\lib\\concurrent\\futures\\_base.py", line 437, in result\n    return self.__get_result()\n  File "C:\\Users\\Ian\\anaconda3\\envs\\qlbt\\lib\\concurrent\\futures\\_base.py", line 389, in __get_result\n    raise self._exception\n  File "C:\\Users\\Ian\\Documents\\Financial testing\\data_pulling\\dump_bin.py", line 500, in _dump_features\n    _future.result()\n  File "C:\\Users\\Ian\\anaconda3\\envs\\qlbt\\lib\\concurrent\\futures\\_base.py", line 437, in result\n    return self.__get_result()\n  File "C:\\Users\\Ian\\anaconda3\\envs\\qlbt\\lib\\concurrent\\futures\\_base.py", line 389, in __get_result\n    raise self._exception\n  File "C:\\Users\\Ian\\Documents\\Financial testing\\data_pulling\\dump_bin.py", line 500, in _dump_features\n    _future.result()\n  File "C:\\Users\\Ian\\anaconda3\\envs\\qlbt\\lib\\concurrent\\futures\\_base.py", line 437, in result\n    return self.__get_result()\n  File "C:\\Users\\Ian\\anaconda3\\envs\\qlbt\\lib\\concurrent\\futures\\_base.py", line 389, in __get_result\n    raise self._exception\n  File "C:\\Users\\Ian\\Documents\\Financial testing\\data_pulling\\dump_bin.py", line 500, in _dump_features\n    _future.result()\n  File "C:\\Users\\Ian\\anaconda3\\envs\\qlbt\\lib\\concurrent\\futures\\_base.py", line 437, in result\n    return self.__get_result()\n  File "C:\\Users\\Ian\\anaconda3\\envs\\qlbt\\lib\\concurrent\\futures\\_base.py", line 389, in __get_result\n    raise self._exception\n  File "C:\\Users\\Ian\\Documents\\Financial testing\\data_pulling\\dump_bin.py", line 500, in _dump_features\n    _future.result()\n  File "C:\\Users\\Ian\\anaconda3\\envs\\qlbt\\lib\\concurrent\\futures\\_base.py", line 437, in result\n    return self.__get_result()\n  File "C:\\Users\\Ian\\anaconda3\\envs\\qlbt\\lib\\concurrent\\futures\\_base.py", line 389, in __get_result\n    raise self._exception\n  File "C:\\Users\\Ian\\Documents\\Financial testing\\data_pulling\\dump_bin.py", line 500, in _dump_features\n    _future.result()\n  File "C:\\Users\\Ian\\anaconda3\\envs\\qlbt\\lib\\concurrent\\futures\\_base.py", line 437, in result\n    return self.__get_result()\n  File "C:\\Users\\Ian\\anaconda3\\envs\\qlbt\\lib\\concurrent\\futures\\_base.py", line 389, in __get_result\n    raise self._exception\n  File "C:\\Users\\Ian\\Documents\\Financial testing\\data_pulling\\dump_bin.py", line 500, in _dump_features\n    _future.result()\n  File "C:\\Users\\Ian\\anaconda3\\envs\\qlbt\\lib\\concurrent\\futures\\_base.py", line 437, in result\n    return self.__get_result()\n  File "C:\\Users\\Ian\\anaconda3\\envs\\qlbt\\lib\\concurrent\\futures\\_base.py", line 389, in __get_result\n    raise self._exception\n  File "C:\\Users\\Ian\\Documents\\Financial testing\\data_pulling\\dump_bin.py", line 500, in _dump_features\n    _future.result()\n  File "C:\\Users\\Ian\\anaconda3\\envs\\qlbt\\lib\\concurrent\\futures\\_base.py", line 437, in result\n    return self.__get_result()\n  File "C:\\Users\\Ian\\anaconda3\\envs\\qlbt\\lib\\concurrent\\futures\\_base.py", line 389, in __get_result\n    raise self._exception\n  File "C:\\Users\\Ian\\Documents\\Financial testing\\data_pulling\\dump_bin.py", line 500, in _dump_features\n    _future.result()\n  File "C:\\Users\\Ian\\anaconda3\\envs\\qlbt\\lib\\concurrent\\futures\\_base.py", line 437, in result\n    return self.__get_result()\n  File "C:\\Users\\Ian\\anaconda3\\envs\\qlbt\\lib\\concurrent\\futures\\_base.py", line 389, in __get_result\n    raise self._exception\n  File "C:\\Users\\Ian\\Documents\\Financial testing\\data_pulling\\dump_bin.py", line 500, in _dump_features\n    _future.result()\n  File "C:\\Users\\Ian\\anaconda3\\envs\\qlbt\\lib\\concurrent\\futures\\_base.py", line 437, in result\n    return self.__get_result()\n  File "C:\\Users\\Ian\\anaconda3\\envs\\qlbt\\lib\\concurrent\\futures\\_base.py", line 389, in __get_result\n    raise self._exception\n  File "C:\\Users\\Ian\\Documents\\Financial testing\\data_pulling\\dump_bin.py", line 500, in _dump_features\n    _future.result()\n  File "C:\\Users\\Ian\\anaconda3\\envs\\qlbt\\lib\\concurrent\\futures\\_base.py", line 437, in result\n    return self.__get_result()\n  File "C:\\Users\\Ian\\anaconda3\\envs\\qlbt\\lib\\concurrent\\futures\\_base.py", line 389, in __get_result\n    raise self._exception\n  File "C:\\Users\\Ian\\Documents\\Financial testing\\data_pulling\\dump_bin.py", line 500, in _dump_features\n    _future.result()\n  File "C:\\Users\\Ian\\anaconda3\\envs\\qlbt\\lib\\concurrent\\futures\\_base.py", line 437, in result\n    return self.__get_result()\n  File "C:\\Users\\Ian\\anaconda3\\envs\\qlbt\\lib\\concurrent\\futures\\_base.py", line 389, in __get_result\n    raise self._exception\n  File "C:\\Users\\Ian\\Documents\\Financial testing\\data_pulling\\dump_bin.py", line 500, in _dump_features\n    _future.result()\n  File "C:\\Users\\Ian\\anaconda3\\envs\\qlbt\\lib\\concurrent\\futures\\_base.py", line 437, in result\n    return self.__get_result()\n  File "C:\\Users\\Ian\\anaconda3\\envs\\qlbt\\lib\\concurrent\\futures\\_base.py", line 389, in __get_result\n    raise self._exception\n  File "C:\\Users\\Ian\\Documents\\Financial testing\\data_pulling\\dump_bin.py", line 500, in _dump_features\n    _future.result()\n  File "C:\\Users\\Ian\\anaconda3\\envs\\qlbt\\lib\\concurrent\\futures\\_base.py", line 437, in result\n    return self.__get_result()\n  File "C:\\Users\\Ian\\anaconda3\\envs\\qlbt\\lib\\concurrent\\futures\\_base.py", line 389, in __get_result\n    raise self._exception\nconcurrent.futures.process.BrokenProcessPool: A process in the process pool was terminated abruptly while the future was running or pending.\n', 'VETBUSD': 'Traceback (most recent call last):\n  File "C:\\Users\\Ian\\Documents\\Financial testing\\data_pulling\\dump_bin.py", line 500, in _dump_features\n    _future.result()\n  File "C:\\Users\\Ian\\anaconda3\\envs\\qlbt\\lib\\concurrent\\futures\\_base.py", line 437, in result\n    return self.__get_result()\n  File "C:\\Users\\Ian\\anaconda3\\envs\\qlbt\\lib\\concurrent\\futures\\_base.py", line 389, in __get_result\n    raise self._exception\n  File "C:\\Users\\Ian\\Documents\\Financial testing\\data_pulling\\dump_bin.py", line 500, in _dump_features\n    _future.result()\n  File "C:\\Users\\Ian\\anaconda3\\envs\\qlbt\\lib\\concurrent\\futures\\_base.py", line 437, in result\n    return self.__get_result()\n  File "C:\\Users\\Ian\\anaconda3\\envs\\qlbt\\lib\\concurrent\\futures\\_base.py", line 389, in __get_result\n    raise self._exception\n  File "C:\\Users\\Ian\\Documents\\Financial testing\\data_pulling\\dump_bin.py", line 500, in _dump_features\n    _future.result()\n  File "C:\\Users\\Ian\\anaconda3\\envs\\qlbt\\lib\\concurrent\\futures\\_base.py", line 437, in result\n    return self.__get_result()\n  File "C:\\Users\\Ian\\anaconda3\\envs\\qlbt\\lib\\concurrent\\futures\\_base.py", line 389, in __get_result\n    raise self._exception\n  File "C:\\Users\\Ian\\Documents\\Financial testing\\data_pulling\\dump_bin.py", line 500, in _dump_features\n    _future.result()\n  File "C:\\Users\\Ian\\anaconda3\\envs\\qlbt\\lib\\concurrent\\futures\\_base.py", line 437, in result\n    return self.__get_result()\n  File "C:\\Users\\Ian\\anaconda3\\envs\\qlbt\\lib\\concurrent\\futures\\_base.py", line 389, in __get_result\n    raise self._exception\n  File "C:\\Users\\Ian\\Documents\\Financial testing\\data_pulling\\dump_bin.py", line 500, in _dump_features\n    _future.result()\n  File "C:\\Users\\Ian\\anaconda3\\envs\\qlbt\\lib\\concurrent\\futures\\_base.py", line 437, in result\n    return self.__get_result()\n  File "C:\\Users\\Ian\\anaconda3\\envs\\qlbt\\lib\\concurrent\\futures\\_base.py", line 389, in __get_result\n    raise self._exception\n  File "C:\\Users\\Ian\\Documents\\Financial testing\\data_pulling\\dump_bin.py", line 500, in _dump_features\n    _future.result()\n  File "C:\\Users\\Ian\\anaconda3\\envs\\qlbt\\lib\\concurrent\\futures\\_base.py", line 437, in result\n    return self.__get_result()\n  File "C:\\Users\\Ian\\anaconda3\\envs\\qlbt\\lib\\concurrent\\futures\\_base.py", line 389, in __get_result\n    raise self._exception\n  File "C:\\Users\\Ian\\Documents\\Financial testing\\data_pulling\\dump_bin.py", line 500, in _dump_features\n    _future.result()\n  File "C:\\Users\\Ian\\anaconda3\\envs\\qlbt\\lib\\concurrent\\futures\\_base.py", line 437, in result\n    return self.__get_result()\n  File "C:\\Users\\Ian\\anaconda3\\envs\\qlbt\\lib\\concurrent\\futures\\_base.py", line 389, in __get_result\n    raise self._exception\n  File "C:\\Users\\Ian\\Documents\\Financial testing\\data_pulling\\dump_bin.py", line 500, in _dump_features\n    _future.result()\n  File "C:\\Users\\Ian\\anaconda3\\envs\\qlbt\\lib\\concurrent\\futures\\_base.py", line 437, in result\n    return self.__get_result()\n  File "C:\\Users\\Ian\\anaconda3\\envs\\qlbt\\lib\\concurrent\\futures\\_base.py", line 389, in __get_result\n    raise self._exception\n  File "C:\\Users\\Ian\\Documents\\Financial testing\\data_pulling\\dump_bin.py", line 500, in _dump_features\n    _future.result()\n  File "C:\\Users\\Ian\\anaconda3\\envs\\qlbt\\lib\\concurrent\\futures\\_base.py", line 437, in result\n    return self.__get_result()\n  File "C:\\Users\\Ian\\anaconda3\\envs\\qlbt\\lib\\concurrent\\futures\\_base.py", line 389, in __get_result\n    raise self._exception\n  File "C:\\Users\\Ian\\Documents\\Financial testing\\data_pulling\\dump_bin.py", line 500, in _dump_features\n    _future.result()\n  File "C:\\Users\\Ian\\anaconda3\\envs\\qlbt\\lib\\concurrent\\futures\\_base.py", line 437, in result\n    return self.__get_result()\n  File "C:\\Users\\Ian\\anaconda3\\envs\\qlbt\\lib\\concurrent\\futures\\_base.py", line 389, in __get_result\n    raise self._exception\n  File "C:\\Users\\Ian\\Documents\\Financial testing\\data_pulling\\dump_bin.py", line 500, in _dump_features\n    _future.result()\n  File "C:\\Users\\Ian\\anaconda3\\envs\\qlbt\\lib\\concurrent\\futures\\_base.py", line 437, in result\n    return self.__get_result()\n  File "C:\\Users\\Ian\\anaconda3\\envs\\qlbt\\lib\\concurrent\\futures\\_base.py", line 389, in __get_result\n    raise self._exception\n  File "C:\\Users\\Ian\\Documents\\Financial testing\\data_pulling\\dump_bin.py", line 500, in _dump_features\n    _future.result()\n  File "C:\\Users\\Ian\\anaconda3\\envs\\qlbt\\lib\\concurrent\\futures\\_base.py", line 437, in result\n    return self.__get_result()\n  File "C:\\Users\\Ian\\anaconda3\\envs\\qlbt\\lib\\concurrent\\futures\\_base.py", line 389, in __get_result\n    raise self._exception\n  File "C:\\Users\\Ian\\Documents\\Financial testing\\data_pulling\\dump_bin.py", line 500, in _dump_features\n    _future.result()\n  File "C:\\Users\\Ian\\anaconda3\\envs\\qlbt\\lib\\concurrent\\futures\\_base.py", line 437, in result\n    return self.__get_result()\n  File "C:\\Users\\Ian\\anaconda3\\envs\\qlbt\\lib\\concurrent\\futures\\_base.py", line 389, in __get_result\n    raise self._exception\n  File "C:\\Users\\Ian\\Documents\\Financial testing\\data_pulling\\dump_bin.py", line 500, in _dump_features\n    _future.result()\n  File "C:\\Users\\Ian\\anaconda3\\envs\\qlbt\\lib\\concurrent\\futures\\_base.py", line 437, in result\n    return self.__get_result()\n  File "C:\\Users\\Ian\\anaconda3\\envs\\qlbt\\lib\\concurrent\\futures\\_base.py", line 389, in __get_result\n    raise self._exception\n  File "C:\\Users\\Ian\\Documents\\Financial testing\\data_pulling\\dump_bin.py", line 500, in _dump_features\n    _future.result()\n  File "C:\\Users\\Ian\\anaconda3\\envs\\qlbt\\lib\\concurrent\\futures\\_base.py", line 437, in result\n    return self.__get_result()\n  File "C:\\Users\\Ian\\anaconda3\\envs\\qlbt\\lib\\concurrent\\futures\\_base.py", line 389, in __get_result\n    raise self._exception\n  File "C:\\Users\\Ian\\Documents\\Financial testing\\data_pulling\\dump_bin.py", line 500, in _dump_features\n    _future.result()\n  File "C:\\Users\\Ian\\anaconda3\\envs\\qlbt\\lib\\concurrent\\futures\\_base.py", line 437, in result\n    return self.__get_result()\n  File "C:\\Users\\Ian\\anaconda3\\envs\\qlbt\\lib\\concurrent\\futures\\_base.py", line 389, in __get_result\n    raise self._exception\n  File "C:\\Users\\Ian\\Documents\\Financial testing\\data_pulling\\dump_bin.py", line 500, in _dump_features\n    _future.result()\n  File "C:\\Users\\Ian\\anaconda3\\envs\\qlbt\\lib\\concurrent\\futures\\_base.py", line 437, in result\n    return self.__get_result()\n  File "C:\\Users\\Ian\\anaconda3\\envs\\qlbt\\lib\\concurrent\\futures\\_base.py", line 389, in __get_result\n    raise self._exception\nconcurrent.futures.process.BrokenProcessPool: A process in the process pool was terminated abruptly while the future was running or pending.\n', 'WAVESBUSD': 'Traceback (most recent call last):\n  File "C:\\Users\\Ian\\Documents\\Financial testing\\data_pulling\\dump_bin.py", line 500, in _dump_features\n    _future.result()\n  File "C:\\Users\\Ian\\anaconda3\\envs\\qlbt\\lib\\concurrent\\futures\\_base.py", line 437, in result\n    return self.__get_result()\n  File "C:\\Users\\Ian\\anaconda3\\envs\\qlbt\\lib\\concurrent\\futures\\_base.py", line 389, in __get_result\n    raise self._exception\n  File "C:\\Users\\Ian\\Documents\\Financial testing\\data_pulling\\dump_bin.py", line 500, in _dump_features\n    _future.result()\n  File "C:\\Users\\Ian\\anaconda3\\envs\\qlbt\\lib\\concurrent\\futures\\_base.py", line 437, in result\n    return self.__get_result()\n  File "C:\\Users\\Ian\\anaconda3\\envs\\qlbt\\lib\\concurrent\\futures\\_base.py", line 389, in __get_result\n    raise self._exception\n  File "C:\\Users\\Ian\\Documents\\Financial testing\\data_pulling\\dump_bin.py", line 500, in _dump_features\n    _future.result()\n  File "C:\\Users\\Ian\\anaconda3\\envs\\qlbt\\lib\\concurrent\\futures\\_base.py", line 437, in result\n    return self.__get_result()\n  File "C:\\Users\\Ian\\anaconda3\\envs\\qlbt\\lib\\concurrent\\futures\\_base.py", line 389, in __get_result\n    raise self._exception\n  File "C:\\Users\\Ian\\Documents\\Financial testing\\data_pulling\\dump_bin.py", line 500, in _dump_features\n    _future.result()\n  File "C:\\Users\\Ian\\anaconda3\\envs\\qlbt\\lib\\concurrent\\futures\\_base.py", line 437, in result\n    return self.__get_result()\n  File "C:\\Users\\Ian\\anaconda3\\envs\\qlbt\\lib\\concurrent\\futures\\_base.py", line 389, in __get_result\n    raise self._exception\n  File "C:\\Users\\Ian\\Documents\\Financial testing\\data_pulling\\dump_bin.py", line 500, in _dump_features\n    _future.result()\n  File "C:\\Users\\Ian\\anaconda3\\envs\\qlbt\\lib\\concurrent\\futures\\_base.py", line 437, in result\n    return self.__get_result()\n  File "C:\\Users\\Ian\\anaconda3\\envs\\qlbt\\lib\\concurrent\\futures\\_base.py", line 389, in __get_result\n    raise self._exception\n  File "C:\\Users\\Ian\\Documents\\Financial testing\\data_pulling\\dump_bin.py", line 500, in _dump_features\n    _future.result()\n  File "C:\\Users\\Ian\\anaconda3\\envs\\qlbt\\lib\\concurrent\\futures\\_base.py", line 437, in result\n    return self.__get_result()\n  File "C:\\Users\\Ian\\anaconda3\\envs\\qlbt\\lib\\concurrent\\futures\\_base.py", line 389, in __get_result\n    raise self._exception\n  File "C:\\Users\\Ian\\Documents\\Financial testing\\data_pulling\\dump_bin.py", line 500, in _dump_features\n    _future.result()\n  File "C:\\Users\\Ian\\anaconda3\\envs\\qlbt\\lib\\concurrent\\futures\\_base.py", line 437, in result\n    return self.__get_result()\n  File "C:\\Users\\Ian\\anaconda3\\envs\\qlbt\\lib\\concurrent\\futures\\_base.py", line 389, in __get_result\n    raise self._exception\n  File "C:\\Users\\Ian\\Documents\\Financial testing\\data_pulling\\dump_bin.py", line 500, in _dump_features\n    _future.result()\n  File "C:\\Users\\Ian\\anaconda3\\envs\\qlbt\\lib\\concurrent\\futures\\_base.py", line 437, in result\n    return self.__get_result()\n  File "C:\\Users\\Ian\\anaconda3\\envs\\qlbt\\lib\\concurrent\\futures\\_base.py", line 389, in __get_result\n    raise self._exception\n  File "C:\\Users\\Ian\\Documents\\Financial testing\\data_pulling\\dump_bin.py", line 500, in _dump_features\n    _future.result()\n  File "C:\\Users\\Ian\\anaconda3\\envs\\qlbt\\lib\\concurrent\\futures\\_base.py", line 437, in result\n    return self.__get_result()\n  File "C:\\Users\\Ian\\anaconda3\\envs\\qlbt\\lib\\concurrent\\futures\\_base.py", line 389, in __get_result\n    raise self._exception\n  File "C:\\Users\\Ian\\Documents\\Financial testing\\data_pulling\\dump_bin.py", line 500, in _dump_features\n    _future.result()\n  File "C:\\Users\\Ian\\anaconda3\\envs\\qlbt\\lib\\concurrent\\futures\\_base.py", line 437, in result\n    return self.__get_result()\n  File "C:\\Users\\Ian\\anaconda3\\envs\\qlbt\\lib\\concurrent\\futures\\_base.py", line 389, in __get_result\n    raise self._exception\n  File "C:\\Users\\Ian\\Documents\\Financial testing\\data_pulling\\dump_bin.py", line 500, in _dump_features\n    _future.result()\n  File "C:\\Users\\Ian\\anaconda3\\envs\\qlbt\\lib\\concurrent\\futures\\_base.py", line 437, in result\n    return self.__get_result()\n  File "C:\\Users\\Ian\\anaconda3\\envs\\qlbt\\lib\\concurrent\\futures\\_base.py", line 389, in __get_result\n    raise self._exception\n  File "C:\\Users\\Ian\\Documents\\Financial testing\\data_pulling\\dump_bin.py", line 500, in _dump_features\n    _future.result()\n  File "C:\\Users\\Ian\\anaconda3\\envs\\qlbt\\lib\\concurrent\\futures\\_base.py", line 437, in result\n    return self.__get_result()\n  File "C:\\Users\\Ian\\anaconda3\\envs\\qlbt\\lib\\concurrent\\futures\\_base.py", line 389, in __get_result\n    raise self._exception\n  File "C:\\Users\\Ian\\Documents\\Financial testing\\data_pulling\\dump_bin.py", line 500, in _dump_features\n    _future.result()\n  File "C:\\Users\\Ian\\anaconda3\\envs\\qlbt\\lib\\concurrent\\futures\\_base.py", line 437, in result\n    return self.__get_result()\n  File "C:\\Users\\Ian\\anaconda3\\envs\\qlbt\\lib\\concurrent\\futures\\_base.py", line 389, in __get_result\n    raise self._exception\n  File "C:\\Users\\Ian\\Documents\\Financial testing\\data_pulling\\dump_bin.py", line 500, in _dump_features\n    _future.result()\n  File "C:\\Users\\Ian\\anaconda3\\envs\\qlbt\\lib\\concurrent\\futures\\_base.py", line 437, in result\n    return self.__get_result()\n  File "C:\\Users\\Ian\\anaconda3\\envs\\qlbt\\lib\\concurrent\\futures\\_base.py", line 389, in __get_result\n    raise self._exception\n  File "C:\\Users\\Ian\\Documents\\Financial testing\\data_pulling\\dump_bin.py", line 500, in _dump_features\n    _future.result()\n  File "C:\\Users\\Ian\\anaconda3\\envs\\qlbt\\lib\\concurrent\\futures\\_base.py", line 437, in result\n    return self.__get_result()\n  File "C:\\Users\\Ian\\anaconda3\\envs\\qlbt\\lib\\concurrent\\futures\\_base.py", line 389, in __get_result\n    raise self._exception\n  File "C:\\Users\\Ian\\Documents\\Financial testing\\data_pulling\\dump_bin.py", line 500, in _dump_features\n    _future.result()\n  File "C:\\Users\\Ian\\anaconda3\\envs\\qlbt\\lib\\concurrent\\futures\\_base.py", line 437, in result\n    return self.__get_result()\n  File "C:\\Users\\Ian\\anaconda3\\envs\\qlbt\\lib\\concurrent\\futures\\_base.py", line 389, in __get_result\n    raise self._exception\n  File "C:\\Users\\Ian\\Documents\\Financial testing\\data_pulling\\dump_bin.py", line 500, in _dump_features\n    _future.result()\n  File "C:\\Users\\Ian\\anaconda3\\envs\\qlbt\\lib\\concurrent\\futures\\_base.py", line 437, in result\n    return self.__get_result()\n  File "C:\\Users\\Ian\\anaconda3\\envs\\qlbt\\lib\\concurrent\\futures\\_base.py", line 389, in __get_result\n    raise self._exception\n  File "C:\\Users\\Ian\\Documents\\Financial testing\\data_pulling\\dump_bin.py", line 500, in _dump_features\n    _future.result()\n  File "C:\\Users\\Ian\\anaconda3\\envs\\qlbt\\lib\\concurrent\\futures\\_base.py", line 437, in result\n    return self.__get_result()\n  File "C:\\Users\\Ian\\anaconda3\\envs\\qlbt\\lib\\concurrent\\futures\\_base.py", line 389, in __get_result\n    raise self._exception\nconcurrent.futures.process.BrokenProcessPool: A process in the process pool was terminated abruptly while the future was running or pending.\n', 'WAXPBUSD': 'Traceback (most recent call last):\n  File "C:\\Users\\Ian\\Documents\\Financial testing\\data_pulling\\dump_bin.py", line 500, in _dump_features\n    _future.result()\n  File "C:\\Users\\Ian\\anaconda3\\envs\\qlbt\\lib\\concurrent\\futures\\_base.py", line 437, in result\n    return self.__get_result()\n  File "C:\\Users\\Ian\\anaconda3\\envs\\qlbt\\lib\\concurrent\\futures\\_base.py", line 389, in __get_result\n    raise self._exception\n  File "C:\\Users\\Ian\\Documents\\Financial testing\\data_pulling\\dump_bin.py", line 500, in _dump_features\n    _future.result()\n  File "C:\\Users\\Ian\\anaconda3\\envs\\qlbt\\lib\\concurrent\\futures\\_base.py", line 437, in result\n    return self.__get_result()\n  File "C:\\Users\\Ian\\anaconda3\\envs\\qlbt\\lib\\concurrent\\futures\\_base.py", line 389, in __get_result\n    raise self._exception\n  File "C:\\Users\\Ian\\Documents\\Financial testing\\data_pulling\\dump_bin.py", line 500, in _dump_features\n    _future.result()\n  File "C:\\Users\\Ian\\anaconda3\\envs\\qlbt\\lib\\concurrent\\futures\\_base.py", line 437, in result\n    return self.__get_result()\n  File "C:\\Users\\Ian\\anaconda3\\envs\\qlbt\\lib\\concurrent\\futures\\_base.py", line 389, in __get_result\n    raise self._exception\n  File "C:\\Users\\Ian\\Documents\\Financial testing\\data_pulling\\dump_bin.py", line 500, in _dump_features\n    _future.result()\n  File "C:\\Users\\Ian\\anaconda3\\envs\\qlbt\\lib\\concurrent\\futures\\_base.py", line 437, in result\n    return self.__get_result()\n  File "C:\\Users\\Ian\\anaconda3\\envs\\qlbt\\lib\\concurrent\\futures\\_base.py", line 389, in __get_result\n    raise self._exception\n  File "C:\\Users\\Ian\\Documents\\Financial testing\\data_pulling\\dump_bin.py", line 500, in _dump_features\n    _future.result()\n  File "C:\\Users\\Ian\\anaconda3\\envs\\qlbt\\lib\\concurrent\\futures\\_base.py", line 437, in result\n    return self.__get_result()\n  File "C:\\Users\\Ian\\anaconda3\\envs\\qlbt\\lib\\concurrent\\futures\\_base.py", line 389, in __get_result\n    raise self._exception\n  File "C:\\Users\\Ian\\Documents\\Financial testing\\data_pulling\\dump_bin.py", line 500, in _dump_features\n    _future.result()\n  File "C:\\Users\\Ian\\anaconda3\\envs\\qlbt\\lib\\concurrent\\futures\\_base.py", line 437, in result\n    return self.__get_result()\n  File "C:\\Users\\Ian\\anaconda3\\envs\\qlbt\\lib\\concurrent\\futures\\_base.py", line 389, in __get_result\n    raise self._exception\n  File "C:\\Users\\Ian\\Documents\\Financial testing\\data_pulling\\dump_bin.py", line 500, in _dump_features\n    _future.result()\n  File "C:\\Users\\Ian\\anaconda3\\envs\\qlbt\\lib\\concurrent\\futures\\_base.py", line 437, in result\n    return self.__get_result()\n  File "C:\\Users\\Ian\\anaconda3\\envs\\qlbt\\lib\\concurrent\\futures\\_base.py", line 389, in __get_result\n    raise self._exception\n  File "C:\\Users\\Ian\\Documents\\Financial testing\\data_pulling\\dump_bin.py", line 500, in _dump_features\n    _future.result()\n  File "C:\\Users\\Ian\\anaconda3\\envs\\qlbt\\lib\\concurrent\\futures\\_base.py", line 437, in result\n    return self.__get_result()\n  File "C:\\Users\\Ian\\anaconda3\\envs\\qlbt\\lib\\concurrent\\futures\\_base.py", line 389, in __get_result\n    raise self._exception\n  File "C:\\Users\\Ian\\Documents\\Financial testing\\data_pulling\\dump_bin.py", line 500, in _dump_features\n    _future.result()\n  File "C:\\Users\\Ian\\anaconda3\\envs\\qlbt\\lib\\concurrent\\futures\\_base.py", line 437, in result\n    return self.__get_result()\n  File "C:\\Users\\Ian\\anaconda3\\envs\\qlbt\\lib\\concurrent\\futures\\_base.py", line 389, in __get_result\n    raise self._exception\n  File "C:\\Users\\Ian\\Documents\\Financial testing\\data_pulling\\dump_bin.py", line 500, in _dump_features\n    _future.result()\n  File "C:\\Users\\Ian\\anaconda3\\envs\\qlbt\\lib\\concurrent\\futures\\_base.py", line 437, in result\n    return self.__get_result()\n  File "C:\\Users\\Ian\\anaconda3\\envs\\qlbt\\lib\\concurrent\\futures\\_base.py", line 389, in __get_result\n    raise self._exception\n  File "C:\\Users\\Ian\\Documents\\Financial testing\\data_pulling\\dump_bin.py", line 500, in _dump_features\n    _future.result()\n  File "C:\\Users\\Ian\\anaconda3\\envs\\qlbt\\lib\\concurrent\\futures\\_base.py", line 437, in result\n    return self.__get_result()\n  File "C:\\Users\\Ian\\anaconda3\\envs\\qlbt\\lib\\concurrent\\futures\\_base.py", line 389, in __get_result\n    raise self._exception\n  File "C:\\Users\\Ian\\Documents\\Financial testing\\data_pulling\\dump_bin.py", line 500, in _dump_features\n    _future.result()\n  File "C:\\Users\\Ian\\anaconda3\\envs\\qlbt\\lib\\concurrent\\futures\\_base.py", line 437, in result\n    return self.__get_result()\n  File "C:\\Users\\Ian\\anaconda3\\envs\\qlbt\\lib\\concurrent\\futures\\_base.py", line 389, in __get_result\n    raise self._exception\n  File "C:\\Users\\Ian\\Documents\\Financial testing\\data_pulling\\dump_bin.py", line 500, in _dump_features\n    _future.result()\n  File "C:\\Users\\Ian\\anaconda3\\envs\\qlbt\\lib\\concurrent\\futures\\_base.py", line 437, in result\n    return self.__get_result()\n  File "C:\\Users\\Ian\\anaconda3\\envs\\qlbt\\lib\\concurrent\\futures\\_base.py", line 389, in __get_result\n    raise self._exception\n  File "C:\\Users\\Ian\\Documents\\Financial testing\\data_pulling\\dump_bin.py", line 500, in _dump_features\n    _future.result()\n  File "C:\\Users\\Ian\\anaconda3\\envs\\qlbt\\lib\\concurrent\\futures\\_base.py", line 437, in result\n    return self.__get_result()\n  File "C:\\Users\\Ian\\anaconda3\\envs\\qlbt\\lib\\concurrent\\futures\\_base.py", line 389, in __get_result\n    raise self._exception\n  File "C:\\Users\\Ian\\Documents\\Financial testing\\data_pulling\\dump_bin.py", line 500, in _dump_features\n    _future.result()\n  File "C:\\Users\\Ian\\anaconda3\\envs\\qlbt\\lib\\concurrent\\futures\\_base.py", line 437, in result\n    return self.__get_result()\n  File "C:\\Users\\Ian\\anaconda3\\envs\\qlbt\\lib\\concurrent\\futures\\_base.py", line 389, in __get_result\n    raise self._exception\n  File "C:\\Users\\Ian\\Documents\\Financial testing\\data_pulling\\dump_bin.py", line 500, in _dump_features\n    _future.result()\n  File "C:\\Users\\Ian\\anaconda3\\envs\\qlbt\\lib\\concurrent\\futures\\_base.py", line 437, in result\n    return self.__get_result()\n  File "C:\\Users\\Ian\\anaconda3\\envs\\qlbt\\lib\\concurrent\\futures\\_base.py", line 389, in __get_result\n    raise self._exception\n  File "C:\\Users\\Ian\\Documents\\Financial testing\\data_pulling\\dump_bin.py", line 500, in _dump_features\n    _future.result()\n  File "C:\\Users\\Ian\\anaconda3\\envs\\qlbt\\lib\\concurrent\\futures\\_base.py", line 437, in result\n    return self.__get_result()\n  File "C:\\Users\\Ian\\anaconda3\\envs\\qlbt\\lib\\concurrent\\futures\\_base.py", line 389, in __get_result\n    raise self._exception\n  File "C:\\Users\\Ian\\Documents\\Financial testing\\data_pulling\\dump_bin.py", line 500, in _dump_features\n    _future.result()\n  File "C:\\Users\\Ian\\anaconda3\\envs\\qlbt\\lib\\concurrent\\futures\\_base.py", line 437, in result\n    return self.__get_result()\n  File "C:\\Users\\Ian\\anaconda3\\envs\\qlbt\\lib\\concurrent\\futures\\_base.py", line 389, in __get_result\n    raise self._exception\n  File "C:\\Users\\Ian\\Documents\\Financial testing\\data_pulling\\dump_bin.py", line 500, in _dump_features\n    _future.result()\n  File "C:\\Users\\Ian\\anaconda3\\envs\\qlbt\\lib\\concurrent\\futures\\_base.py", line 437, in result\n    return self.__get_result()\n  File "C:\\Users\\Ian\\anaconda3\\envs\\qlbt\\lib\\concurrent\\futures\\_base.py", line 389, in __get_result\n    raise self._exception\nconcurrent.futures.process.BrokenProcessPool: A process in the process pool was terminated abruptly while the future was running or pending.\n'}
C:\Users\Ian\anaconda3\envs\qlbt\lib\site-packages\dateparser\date_parser.py:35: PytzUsageWarning:

The localize method is no longer necessary, as this time zone supports the fold attribute (PEP 495). For more details on migrating to a PEP 495-compliant implementation, see https://pytz-deprecation-shim.readthedocs.io/en/latest/migration.html

2022-08-05 23:09:16.374 | INFO     | data_pulling.dump_bin:_load_all_source_data:443 - start load all source data....
2022-08-05 23:09:16.417 | INFO     | data_pulling.dump_bin:_load_all_source_data:459 - end of load all data.

2022-08-05 23:09:16.507 | INFO     | data_pulling.dump_bin:_dump_features:469 - start dump features......
2022-08-05 23:09:19.324 | INFO     | data_pulling.dump_bin:_dump_features:505 - dump bin errors： {'ADABUSD': 'Traceback (most recent call last):\n  File "C:\\Users\\Ian\\Documents\\Financial testing\\data_pulling\\dump_bin.py", line 500, in _dump_features\n    _future.result()\n  File "C:\\Users\\Ian\\anaconda3\\envs\\qlbt\\lib\\concurrent\\futures\\_base.py", line 437, in result\n    return self.__get_result()\n  File "C:\\Users\\Ian\\anaconda3\\envs\\qlbt\\lib\\concurrent\\futures\\_base.py", line 389, in __get_result\n    raise self._exception\nconcurrent.futures.process.BrokenProcessPool: A process in the process pool was terminated abruptly while the future was running or pending.\n', 'ALGOBUSD': 'Traceback (most recent call last):\n  File "C:\\Users\\Ian\\Documents\\Financial testing\\data_pulling\\dump_bin.py", line 500, in _dump_features\n    _future.result()\n  File "C:\\Users\\Ian\\anaconda3\\envs\\qlbt\\lib\\concurrent\\futures\\_base.py", line 437, in result\n    return self.__get_result()\n  File "C:\\Users\\Ian\\anaconda3\\envs\\qlbt\\lib\\concurrent\\futures\\_base.py", line 389, in __get_result\n    raise self._exception\n  File "C:\\Users\\Ian\\Documents\\Financial testing\\data_pulling\\dump_bin.py", line 500, in _dump_features\n    _future.result()\n  File "C:\\Users\\Ian\\anaconda3\\envs\\qlbt\\lib\\concurrent\\futures\\_base.py", line 437, in result\n    return self.__get_result()\n  File "C:\\Users\\Ian\\anaconda3\\envs\\qlbt\\lib\\concurrent\\futures\\_base.py", line 389, in __get_result\n    raise self._exception\nconcurrent.futures.process.BrokenProcessPool: A process in the process pool was terminated abruptly while the future was running or pending.\n', 'ATOMBUSD': 'Traceback (most recent call last):\n  File "C:\\Users\\Ian\\Documents\\Financial testing\\data_pulling\\dump_bin.py", line 500, in _dump_features\n    _future.result()\n  File "C:\\Users\\Ian\\anaconda3\\envs\\qlbt\\lib\\concurrent\\futures\\_base.py", line 437, in result\n    return self.__get_result()\n  File "C:\\Users\\Ian\\anaconda3\\envs\\qlbt\\lib\\concurrent\\futures\\_base.py", line 389, in __get_result\n    raise self._exception\n  File "C:\\Users\\Ian\\Documents\\Financial testing\\data_pulling\\dump_bin.py", line 500, in _dump_features\n    _future.result()\n  File "C:\\Users\\Ian\\anaconda3\\envs\\qlbt\\lib\\concurrent\\futures\\_base.py", line 437, in result\n    return self.__get_result()\n  File "C:\\Users\\Ian\\anaconda3\\envs\\qlbt\\lib\\concurrent\\futures\\_base.py", line 389, in __get_result\n    raise self._exception\n  File "C:\\Users\\Ian\\Documents\\Financial testing\\data_pulling\\dump_bin.py", line 500, in _dump_features\n    _future.result()\n  File "C:\\Users\\Ian\\anaconda3\\envs\\qlbt\\lib\\concurrent\\futures\\_base.py", line 437, in result\n    return self.__get_result()\n  File "C:\\Users\\Ian\\anaconda3\\envs\\qlbt\\lib\\concurrent\\futures\\_base.py", line 389, in __get_result\n    raise self._exception\nconcurrent.futures.process.BrokenProcessPool: A process in the process pool was terminated abruptly while the future was running or pending.\n', 'AVAXBUSD': 'Traceback (most recent call last):\n  File "C:\\Users\\Ian\\Documents\\Financial testing\\data_pulling\\dump_bin.py", line 500, in _dump_features\n    _future.result()\n  File "C:\\Users\\Ian\\anaconda3\\envs\\qlbt\\lib\\concurrent\\futures\\_base.py", line 437, in result\n    return self.__get_result()\n  File "C:\\Users\\Ian\\anaconda3\\envs\\qlbt\\lib\\concurrent\\futures\\_base.py", line 389, in __get_result\n    raise self._exception\n  File "C:\\Users\\Ian\\Documents\\Financial testing\\data_pulling\\dump_bin.py", line 500, in _dump_features\n    _future.result()\n  File "C:\\Users\\Ian\\anaconda3\\envs\\qlbt\\lib\\concurrent\\futures\\_base.py", line 437, in result\n    return self.__get_result()\n  File "C:\\Users\\Ian\\anaconda3\\envs\\qlbt\\lib\\concurrent\\futures\\_base.py", line 389, in __get_result\n    raise self._exception\n  File "C:\\Users\\Ian\\Documents\\Financial testing\\data_pulling\\dump_bin.py", line 500, in _dump_features\n    _future.result()\n  File "C:\\Users\\Ian\\anaconda3\\envs\\qlbt\\lib\\concurrent\\futures\\_base.py", line 437, in result\n    return self.__get_result()\n  File "C:\\Users\\Ian\\anaconda3\\envs\\qlbt\\lib\\concurrent\\futures\\_base.py", line 389, in __get_result\n    raise self._exception\n  File "C:\\Users\\Ian\\Documents\\Financial testing\\data_pulling\\dump_bin.py", line 500, in _dump_features\n    _future.result()\n  File "C:\\Users\\Ian\\anaconda3\\envs\\qlbt\\lib\\concurrent\\futures\\_base.py", line 437, in result\n    return self.__get_result()\n  File "C:\\Users\\Ian\\anaconda3\\envs\\qlbt\\lib\\concurrent\\futures\\_base.py", line 389, in __get_result\n    raise self._exception\nconcurrent.futures.process.BrokenProcessPool: A process in the process pool was terminated abruptly while the future was running or pending.\n', 'BNBBUSD': 'Traceback (most recent call last):\n  File "C:\\Users\\Ian\\Documents\\Financial testing\\data_pulling\\dump_bin.py", line 500, in _dump_features\n    _future.result()\n  File "C:\\Users\\Ian\\anaconda3\\envs\\qlbt\\lib\\concurrent\\futures\\_base.py", line 437, in result\n    return self.__get_result()\n  File "C:\\Users\\Ian\\anaconda3\\envs\\qlbt\\lib\\concurrent\\futures\\_base.py", line 389, in __get_result\n    raise self._exception\n  File "C:\\Users\\Ian\\Documents\\Financial testing\\data_pulling\\dump_bin.py", line 500, in _dump_features\n    _future.result()\n  File "C:\\Users\\Ian\\anaconda3\\envs\\qlbt\\lib\\concurrent\\futures\\_base.py", line 437, in result\n    return self.__get_result()\n  File "C:\\Users\\Ian\\anaconda3\\envs\\qlbt\\lib\\concurrent\\futures\\_base.py", line 389, in __get_result\n    raise self._exception\n  File "C:\\Users\\Ian\\Documents\\Financial testing\\data_pulling\\dump_bin.py", line 500, in _dump_features\n    _future.result()\n  File "C:\\Users\\Ian\\anaconda3\\envs\\qlbt\\lib\\concurrent\\futures\\_base.py", line 437, in result\n    return self.__get_result()\n  File "C:\\Users\\Ian\\anaconda3\\envs\\qlbt\\lib\\concurrent\\futures\\_base.py", line 389, in __get_result\n    raise self._exception\n  File "C:\\Users\\Ian\\Documents\\Financial testing\\data_pulling\\dump_bin.py", line 500, in _dump_features\n    _future.result()\n  File "C:\\Users\\Ian\\anaconda3\\envs\\qlbt\\lib\\concurrent\\futures\\_base.py", line 437, in result\n    return self.__get_result()\n  File "C:\\Users\\Ian\\anaconda3\\envs\\qlbt\\lib\\concurrent\\futures\\_base.py", line 389, in __get_result\n    raise self._exception\n  File "C:\\Users\\Ian\\Documents\\Financial testing\\data_pulling\\dump_bin.py", line 500, in _dump_features\n    _future.result()\n  File "C:\\Users\\Ian\\anaconda3\\envs\\qlbt\\lib\\concurrent\\futures\\_base.py", line 437, in result\n    return self.__get_result()\n  File "C:\\Users\\Ian\\anaconda3\\envs\\qlbt\\lib\\concurrent\\futures\\_base.py", line 389, in __get_result\n    raise self._exception\nconcurrent.futures.process.BrokenProcessPool: A process in the process pool was terminated abruptly while the future was running or pending.\n', 'BTCBUSD': 'Traceback (most recent call last):\n  File "C:\\Users\\Ian\\Documents\\Financial testing\\data_pulling\\dump_bin.py", line 500, in _dump_features\n    _future.result()\n  File "C:\\Users\\Ian\\anaconda3\\envs\\qlbt\\lib\\concurrent\\futures\\_base.py", line 437, in result\n    return self.__get_result()\n  File "C:\\Users\\Ian\\anaconda3\\envs\\qlbt\\lib\\concurrent\\futures\\_base.py", line 389, in __get_result\n    raise self._exception\n  File "C:\\Users\\Ian\\Documents\\Financial testing\\data_pulling\\dump_bin.py", line 500, in _dump_features\n    _future.result()\n  File "C:\\Users\\Ian\\anaconda3\\envs\\qlbt\\lib\\concurrent\\futures\\_base.py", line 437, in result\n    return self.__get_result()\n  File "C:\\Users\\Ian\\anaconda3\\envs\\qlbt\\lib\\concurrent\\futures\\_base.py", line 389, in __get_result\n    raise self._exception\n  File "C:\\Users\\Ian\\Documents\\Financial testing\\data_pulling\\dump_bin.py", line 500, in _dump_features\n    _future.result()\n  File "C:\\Users\\Ian\\anaconda3\\envs\\qlbt\\lib\\concurrent\\futures\\_base.py", line 437, in result\n    return self.__get_result()\n  File "C:\\Users\\Ian\\anaconda3\\envs\\qlbt\\lib\\concurrent\\futures\\_base.py", line 389, in __get_result\n    raise self._exception\n  File "C:\\Users\\Ian\\Documents\\Financial testing\\data_pulling\\dump_bin.py", line 500, in _dump_features\n    _future.result()\n  File "C:\\Users\\Ian\\anaconda3\\envs\\qlbt\\lib\\concurrent\\futures\\_base.py", line 437, in result\n    return self.__get_result()\n  File "C:\\Users\\Ian\\anaconda3\\envs\\qlbt\\lib\\concurrent\\futures\\_base.py", line 389, in __get_result\n    raise self._exception\n  File "C:\\Users\\Ian\\Documents\\Financial testing\\data_pulling\\dump_bin.py", line 500, in _dump_features\n    _future.result()\n  File "C:\\Users\\Ian\\anaconda3\\envs\\qlbt\\lib\\concurrent\\futures\\_base.py", line 437, in result\n    return self.__get_result()\n  File "C:\\Users\\Ian\\anaconda3\\envs\\qlbt\\lib\\concurrent\\futures\\_base.py", line 389, in __get_result\n    raise self._exception\n  File "C:\\Users\\Ian\\Documents\\Financial testing\\data_pulling\\dump_bin.py", line 500, in _dump_features\n    _future.result()\n  File "C:\\Users\\Ian\\anaconda3\\envs\\qlbt\\lib\\concurrent\\futures\\_base.py", line 437, in result\n    return self.__get_result()\n  File "C:\\Users\\Ian\\anaconda3\\envs\\qlbt\\lib\\concurrent\\futures\\_base.py", line 389, in __get_result\n    raise self._exception\nconcurrent.futures.process.BrokenProcessPool: A process in the process pool was terminated abruptly while the future was running or pending.\n', 'DOTBUSD': 'Traceback (most recent call last):\n  File "C:\\Users\\Ian\\Documents\\Financial testing\\data_pulling\\dump_bin.py", line 500, in _dump_features\n    _future.result()\n  File "C:\\Users\\Ian\\anaconda3\\envs\\qlbt\\lib\\concurrent\\futures\\_base.py", line 437, in result\n    return self.__get_result()\n  File "C:\\Users\\Ian\\anaconda3\\envs\\qlbt\\lib\\concurrent\\futures\\_base.py", line 389, in __get_result\n    raise self._exception\n  File "C:\\Users\\Ian\\Documents\\Financial testing\\data_pulling\\dump_bin.py", line 500, in _dump_features\n    _future.result()\n  File "C:\\Users\\Ian\\anaconda3\\envs\\qlbt\\lib\\concurrent\\futures\\_base.py", line 437, in result\n    return self.__get_result()\n  File "C:\\Users\\Ian\\anaconda3\\envs\\qlbt\\lib\\concurrent\\futures\\_base.py", line 389, in __get_result\n    raise self._exception\n  File "C:\\Users\\Ian\\Documents\\Financial testing\\data_pulling\\dump_bin.py", line 500, in _dump_features\n    _future.result()\n  File "C:\\Users\\Ian\\anaconda3\\envs\\qlbt\\lib\\concurrent\\futures\\_base.py", line 437, in result\n    return self.__get_result()\n  File "C:\\Users\\Ian\\anaconda3\\envs\\qlbt\\lib\\concurrent\\futures\\_base.py", line 389, in __get_result\n    raise self._exception\n  File "C:\\Users\\Ian\\Documents\\Financial testing\\data_pulling\\dump_bin.py", line 500, in _dump_features\n    _future.result()\n  File "C:\\Users\\Ian\\anaconda3\\envs\\qlbt\\lib\\concurrent\\futures\\_base.py", line 437, in result\n    return self.__get_result()\n  File "C:\\Users\\Ian\\anaconda3\\envs\\qlbt\\lib\\concurrent\\futures\\_base.py", line 389, in __get_result\n    raise self._exception\n  File "C:\\Users\\Ian\\Documents\\Financial testing\\data_pulling\\dump_bin.py", line 500, in _dump_features\n    _future.result()\n  File "C:\\Users\\Ian\\anaconda3\\envs\\qlbt\\lib\\concurrent\\futures\\_base.py", line 437, in result\n    return self.__get_result()\n  File "C:\\Users\\Ian\\anaconda3\\envs\\qlbt\\lib\\concurrent\\futures\\_base.py", line 389, in __get_result\n    raise self._exception\n  File "C:\\Users\\Ian\\Documents\\Financial testing\\data_pulling\\dump_bin.py", line 500, in _dump_features\n    _future.result()\n  File "C:\\Users\\Ian\\anaconda3\\envs\\qlbt\\lib\\concurrent\\futures\\_base.py", line 437, in result\n    return self.__get_result()\n  File "C:\\Users\\Ian\\anaconda3\\envs\\qlbt\\lib\\concurrent\\futures\\_base.py", line 389, in __get_result\n    raise self._exception\n  File "C:\\Users\\Ian\\Documents\\Financial testing\\data_pulling\\dump_bin.py", line 500, in _dump_features\n    _future.result()\n  File "C:\\Users\\Ian\\anaconda3\\envs\\qlbt\\lib\\concurrent\\futures\\_base.py", line 437, in result\n    return self.__get_result()\n  File "C:\\Users\\Ian\\anaconda3\\envs\\qlbt\\lib\\concurrent\\futures\\_base.py", line 389, in __get_result\n    raise self._exception\nconcurrent.futures.process.BrokenProcessPool: A process in the process pool was terminated abruptly while the future was running or pending.\n', 'EOSBUSD': 'Traceback (most recent call last):\n  File "C:\\Users\\Ian\\Documents\\Financial testing\\data_pulling\\dump_bin.py", line 500, in _dump_features\n    _future.result()\n  File "C:\\Users\\Ian\\anaconda3\\envs\\qlbt\\lib\\concurrent\\futures\\_base.py", line 437, in result\n    return self.__get_result()\n  File "C:\\Users\\Ian\\anaconda3\\envs\\qlbt\\lib\\concurrent\\futures\\_base.py", line 389, in __get_result\n    raise self._exception\n  File "C:\\Users\\Ian\\Documents\\Financial testing\\data_pulling\\dump_bin.py", line 500, in _dump_features\n    _future.result()\n  File "C:\\Users\\Ian\\anaconda3\\envs\\qlbt\\lib\\concurrent\\futures\\_base.py", line 437, in result\n    return self.__get_result()\n  File "C:\\Users\\Ian\\anaconda3\\envs\\qlbt\\lib\\concurrent\\futures\\_base.py", line 389, in __get_result\n    raise self._exception\n  File "C:\\Users\\Ian\\Documents\\Financial testing\\data_pulling\\dump_bin.py", line 500, in _dump_features\n    _future.result()\n  File "C:\\Users\\Ian\\anaconda3\\envs\\qlbt\\lib\\concurrent\\futures\\_base.py", line 437, in result\n    return self.__get_result()\n  File "C:\\Users\\Ian\\anaconda3\\envs\\qlbt\\lib\\concurrent\\futures\\_base.py", line 389, in __get_result\n    raise self._exception\n  File "C:\\Users\\Ian\\Documents\\Financial testing\\data_pulling\\dump_bin.py", line 500, in _dump_features\n    _future.result()\n  File "C:\\Users\\Ian\\anaconda3\\envs\\qlbt\\lib\\concurrent\\futures\\_base.py", line 437, in result\n    return self.__get_result()\n  File "C:\\Users\\Ian\\anaconda3\\envs\\qlbt\\lib\\concurrent\\futures\\_base.py", line 389, in __get_result\n    raise self._exception\n  File "C:\\Users\\Ian\\Documents\\Financial testing\\data_pulling\\dump_bin.py", line 500, in _dump_features\n    _future.result()\n  File "C:\\Users\\Ian\\anaconda3\\envs\\qlbt\\lib\\concurrent\\futures\\_base.py", line 437, in result\n    return self.__get_result()\n  File "C:\\Users\\Ian\\anaconda3\\envs\\qlbt\\lib\\concurrent\\futures\\_base.py", line 389, in __get_result\n    raise self._exception\n  File "C:\\Users\\Ian\\Documents\\Financial testing\\data_pulling\\dump_bin.py", line 500, in _dump_features\n    _future.result()\n  File "C:\\Users\\Ian\\anaconda3\\envs\\qlbt\\lib\\concurrent\\futures\\_base.py", line 437, in result\n    return self.__get_result()\n  File "C:\\Users\\Ian\\anaconda3\\envs\\qlbt\\lib\\concurrent\\futures\\_base.py", line 389, in __get_result\n    raise self._exception\n  File "C:\\Users\\Ian\\Documents\\Financial testing\\data_pulling\\dump_bin.py", line 500, in _dump_features\n    _future.result()\n  File "C:\\Users\\Ian\\anaconda3\\envs\\qlbt\\lib\\concurrent\\futures\\_base.py", line 437, in result\n    return self.__get_result()\n  File "C:\\Users\\Ian\\anaconda3\\envs\\qlbt\\lib\\concurrent\\futures\\_base.py", line 389, in __get_result\n    raise self._exception\n  File "C:\\Users\\Ian\\Documents\\Financial testing\\data_pulling\\dump_bin.py", line 500, in _dump_features\n    _future.result()\n  File "C:\\Users\\Ian\\anaconda3\\envs\\qlbt\\lib\\concurrent\\futures\\_base.py", line 437, in result\n    return self.__get_result()\n  File "C:\\Users\\Ian\\anaconda3\\envs\\qlbt\\lib\\concurrent\\futures\\_base.py", line 389, in __get_result\n    raise self._exception\nconcurrent.futures.process.BrokenProcessPool: A process in the process pool was terminated abruptly while the future was running or pending.\n', 'ETHBUSD': 'Traceback (most recent call last):\n  File "C:\\Users\\Ian\\Documents\\Financial testing\\data_pulling\\dump_bin.py", line 500, in _dump_features\n    _future.result()\n  File "C:\\Users\\Ian\\anaconda3\\envs\\qlbt\\lib\\concurrent\\futures\\_base.py", line 437, in result\n    return self.__get_result()\n  File "C:\\Users\\Ian\\anaconda3\\envs\\qlbt\\lib\\concurrent\\futures\\_base.py", line 389, in __get_result\n    raise self._exception\n  File "C:\\Users\\Ian\\Documents\\Financial testing\\data_pulling\\dump_bin.py", line 500, in _dump_features\n    _future.result()\n  File "C:\\Users\\Ian\\anaconda3\\envs\\qlbt\\lib\\concurrent\\futures\\_base.py", line 437, in result\n    return self.__get_result()\n  File "C:\\Users\\Ian\\anaconda3\\envs\\qlbt\\lib\\concurrent\\futures\\_base.py", line 389, in __get_result\n    raise self._exception\n  File "C:\\Users\\Ian\\Documents\\Financial testing\\data_pulling\\dump_bin.py", line 500, in _dump_features\n    _future.result()\n  File "C:\\Users\\Ian\\anaconda3\\envs\\qlbt\\lib\\concurrent\\futures\\_base.py", line 437, in result\n    return self.__get_result()\n  File "C:\\Users\\Ian\\anaconda3\\envs\\qlbt\\lib\\concurrent\\futures\\_base.py", line 389, in __get_result\n    raise self._exception\n  File "C:\\Users\\Ian\\Documents\\Financial testing\\data_pulling\\dump_bin.py", line 500, in _dump_features\n    _future.result()\n  File "C:\\Users\\Ian\\anaconda3\\envs\\qlbt\\lib\\concurrent\\futures\\_base.py", line 437, in result\n    return self.__get_result()\n  File "C:\\Users\\Ian\\anaconda3\\envs\\qlbt\\lib\\concurrent\\futures\\_base.py", line 389, in __get_result\n    raise self._exception\n  File "C:\\Users\\Ian\\Documents\\Financial testing\\data_pulling\\dump_bin.py", line 500, in _dump_features\n    _future.result()\n  File "C:\\Users\\Ian\\anaconda3\\envs\\qlbt\\lib\\concurrent\\futures\\_base.py", line 437, in result\n    return self.__get_result()\n  File "C:\\Users\\Ian\\anaconda3\\envs\\qlbt\\lib\\concurrent\\futures\\_base.py", line 389, in __get_result\n    raise self._exception\n  File "C:\\Users\\Ian\\Documents\\Financial testing\\data_pulling\\dump_bin.py", line 500, in _dump_features\n    _future.result()\n  File "C:\\Users\\Ian\\anaconda3\\envs\\qlbt\\lib\\concurrent\\futures\\_base.py", line 437, in result\n    return self.__get_result()\n  File "C:\\Users\\Ian\\anaconda3\\envs\\qlbt\\lib\\concurrent\\futures\\_base.py", line 389, in __get_result\n    raise self._exception\n  File "C:\\Users\\Ian\\Documents\\Financial testing\\data_pulling\\dump_bin.py", line 500, in _dump_features\n    _future.result()\n  File "C:\\Users\\Ian\\anaconda3\\envs\\qlbt\\lib\\concurrent\\futures\\_base.py", line 437, in result\n    return self.__get_result()\n  File "C:\\Users\\Ian\\anaconda3\\envs\\qlbt\\lib\\concurrent\\futures\\_base.py", line 389, in __get_result\n    raise self._exception\n  File "C:\\Users\\Ian\\Documents\\Financial testing\\data_pulling\\dump_bin.py", line 500, in _dump_features\n    _future.result()\n  File "C:\\Users\\Ian\\anaconda3\\envs\\qlbt\\lib\\concurrent\\futures\\_base.py", line 437, in result\n    return self.__get_result()\n  File "C:\\Users\\Ian\\anaconda3\\envs\\qlbt\\lib\\concurrent\\futures\\_base.py", line 389, in __get_result\n    raise self._exception\n  File "C:\\Users\\Ian\\Documents\\Financial testing\\data_pulling\\dump_bin.py", line 500, in _dump_features\n    _future.result()\n  File "C:\\Users\\Ian\\anaconda3\\envs\\qlbt\\lib\\concurrent\\futures\\_base.py", line 437, in result\n    return self.__get_result()\n  File "C:\\Users\\Ian\\anaconda3\\envs\\qlbt\\lib\\concurrent\\futures\\_base.py", line 389, in __get_result\n    raise self._exception\nconcurrent.futures.process.BrokenProcessPool: A process in the process pool was terminated abruptly while the future was running or pending.\n', 'FTMBUSD': 'Traceback (most recent call last):\n  File "C:\\Users\\Ian\\Documents\\Financial testing\\data_pulling\\dump_bin.py", line 500, in _dump_features\n    _future.result()\n  File "C:\\Users\\Ian\\anaconda3\\envs\\qlbt\\lib\\concurrent\\futures\\_base.py", line 437, in result\n    return self.__get_result()\n  File "C:\\Users\\Ian\\anaconda3\\envs\\qlbt\\lib\\concurrent\\futures\\_base.py", line 389, in __get_result\n    raise self._exception\n  File "C:\\Users\\Ian\\Documents\\Financial testing\\data_pulling\\dump_bin.py", line 500, in _dump_features\n    _future.result()\n  File "C:\\Users\\Ian\\anaconda3\\envs\\qlbt\\lib\\concurrent\\futures\\_base.py", line 437, in result\n    return self.__get_result()\n  File "C:\\Users\\Ian\\anaconda3\\envs\\qlbt\\lib\\concurrent\\futures\\_base.py", line 389, in __get_result\n    raise self._exception\n  File "C:\\Users\\Ian\\Documents\\Financial testing\\data_pulling\\dump_bin.py", line 500, in _dump_features\n    _future.result()\n  File "C:\\Users\\Ian\\anaconda3\\envs\\qlbt\\lib\\concurrent\\futures\\_base.py", line 437, in result\n    return self.__get_result()\n  File "C:\\Users\\Ian\\anaconda3\\envs\\qlbt\\lib\\concurrent\\futures\\_base.py", line 389, in __get_result\n    raise self._exception\n  File "C:\\Users\\Ian\\Documents\\Financial testing\\data_pulling\\dump_bin.py", line 500, in _dump_features\n    _future.result()\n  File "C:\\Users\\Ian\\anaconda3\\envs\\qlbt\\lib\\concurrent\\futures\\_base.py", line 437, in result\n    return self.__get_result()\n  File "C:\\Users\\Ian\\anaconda3\\envs\\qlbt\\lib\\concurrent\\futures\\_base.py", line 389, in __get_result\n    raise self._exception\n  File "C:\\Users\\Ian\\Documents\\Financial testing\\data_pulling\\dump_bin.py", line 500, in _dump_features\n    _future.result()\n  File "C:\\Users\\Ian\\anaconda3\\envs\\qlbt\\lib\\concurrent\\futures\\_base.py", line 437, in result\n    return self.__get_result()\n  File "C:\\Users\\Ian\\anaconda3\\envs\\qlbt\\lib\\concurrent\\futures\\_base.py", line 389, in __get_result\n    raise self._exception\n  File "C:\\Users\\Ian\\Documents\\Financial testing\\data_pulling\\dump_bin.py", line 500, in _dump_features\n    _future.result()\n  File "C:\\Users\\Ian\\anaconda3\\envs\\qlbt\\lib\\concurrent\\futures\\_base.py", line 437, in result\n    return self.__get_result()\n  File "C:\\Users\\Ian\\anaconda3\\envs\\qlbt\\lib\\concurrent\\futures\\_base.py", line 389, in __get_result\n    raise self._exception\n  File "C:\\Users\\Ian\\Documents\\Financial testing\\data_pulling\\dump_bin.py", line 500, in _dump_features\n    _future.result()\n  File "C:\\Users\\Ian\\anaconda3\\envs\\qlbt\\lib\\concurrent\\futures\\_base.py", line 437, in result\n    return self.__get_result()\n  File "C:\\Users\\Ian\\anaconda3\\envs\\qlbt\\lib\\concurrent\\futures\\_base.py", line 389, in __get_result\n    raise self._exception\n  File "C:\\Users\\Ian\\Documents\\Financial testing\\data_pulling\\dump_bin.py", line 500, in _dump_features\n    _future.result()\n  File "C:\\Users\\Ian\\anaconda3\\envs\\qlbt\\lib\\concurrent\\futures\\_base.py", line 437, in result\n    return self.__get_result()\n  File "C:\\Users\\Ian\\anaconda3\\envs\\qlbt\\lib\\concurrent\\futures\\_base.py", line 389, in __get_result\n    raise self._exception\n  File "C:\\Users\\Ian\\Documents\\Financial testing\\data_pulling\\dump_bin.py", line 500, in _dump_features\n    _future.result()\n  File "C:\\Users\\Ian\\anaconda3\\envs\\qlbt\\lib\\concurrent\\futures\\_base.py", line 437, in result\n    return self.__get_result()\n  File "C:\\Users\\Ian\\anaconda3\\envs\\qlbt\\lib\\concurrent\\futures\\_base.py", line 389, in __get_result\n    raise self._exception\n  File "C:\\Users\\Ian\\Documents\\Financial testing\\data_pulling\\dump_bin.py", line 500, in _dump_features\n    _future.result()\n  File "C:\\Users\\Ian\\anaconda3\\envs\\qlbt\\lib\\concurrent\\futures\\_base.py", line 437, in result\n    return self.__get_result()\n  File "C:\\Users\\Ian\\anaconda3\\envs\\qlbt\\lib\\concurrent\\futures\\_base.py", line 389, in __get_result\n    raise self._exception\nconcurrent.futures.process.BrokenProcessPool: A process in the process pool was terminated abruptly while the future was running or pending.\n', 'ICPBUSD': 'Traceback (most recent call last):\n  File "C:\\Users\\Ian\\Documents\\Financial testing\\data_pulling\\dump_bin.py", line 500, in _dump_features\n    _future.result()\n  File "C:\\Users\\Ian\\anaconda3\\envs\\qlbt\\lib\\concurrent\\futures\\_base.py", line 437, in result\n    return self.__get_result()\n  File "C:\\Users\\Ian\\anaconda3\\envs\\qlbt\\lib\\concurrent\\futures\\_base.py", line 389, in __get_result\n    raise self._exception\n  File "C:\\Users\\Ian\\Documents\\Financial testing\\data_pulling\\dump_bin.py", line 500, in _dump_features\n    _future.result()\n  File "C:\\Users\\Ian\\anaconda3\\envs\\qlbt\\lib\\concurrent\\futures\\_base.py", line 437, in result\n    return self.__get_result()\n  File "C:\\Users\\Ian\\anaconda3\\envs\\qlbt\\lib\\concurrent\\futures\\_base.py", line 389, in __get_result\n    raise self._exception\n  File "C:\\Users\\Ian\\Documents\\Financial testing\\data_pulling\\dump_bin.py", line 500, in _dump_features\n    _future.result()\n  File "C:\\Users\\Ian\\anaconda3\\envs\\qlbt\\lib\\concurrent\\futures\\_base.py", line 437, in result\n    return self.__get_result()\n  File "C:\\Users\\Ian\\anaconda3\\envs\\qlbt\\lib\\concurrent\\futures\\_base.py", line 389, in __get_result\n    raise self._exception\n  File "C:\\Users\\Ian\\Documents\\Financial testing\\data_pulling\\dump_bin.py", line 500, in _dump_features\n    _future.result()\n  File "C:\\Users\\Ian\\anaconda3\\envs\\qlbt\\lib\\concurrent\\futures\\_base.py", line 437, in result\n    return self.__get_result()\n  File "C:\\Users\\Ian\\anaconda3\\envs\\qlbt\\lib\\concurrent\\futures\\_base.py", line 389, in __get_result\n    raise self._exception\n  File "C:\\Users\\Ian\\Documents\\Financial testing\\data_pulling\\dump_bin.py", line 500, in _dump_features\n    _future.result()\n  File "C:\\Users\\Ian\\anaconda3\\envs\\qlbt\\lib\\concurrent\\futures\\_base.py", line 437, in result\n    return self.__get_result()\n  File "C:\\Users\\Ian\\anaconda3\\envs\\qlbt\\lib\\concurrent\\futures\\_base.py", line 389, in __get_result\n    raise self._exception\n  File "C:\\Users\\Ian\\Documents\\Financial testing\\data_pulling\\dump_bin.py", line 500, in _dump_features\n    _future.result()\n  File "C:\\Users\\Ian\\anaconda3\\envs\\qlbt\\lib\\concurrent\\futures\\_base.py", line 437, in result\n    return self.__get_result()\n  File "C:\\Users\\Ian\\anaconda3\\envs\\qlbt\\lib\\concurrent\\futures\\_base.py", line 389, in __get_result\n    raise self._exception\n  File "C:\\Users\\Ian\\Documents\\Financial testing\\data_pulling\\dump_bin.py", line 500, in _dump_features\n    _future.result()\n  File "C:\\Users\\Ian\\anaconda3\\envs\\qlbt\\lib\\concurrent\\futures\\_base.py", line 437, in result\n    return self.__get_result()\n  File "C:\\Users\\Ian\\anaconda3\\envs\\qlbt\\lib\\concurrent\\futures\\_base.py", line 389, in __get_result\n    raise self._exception\n  File "C:\\Users\\Ian\\Documents\\Financial testing\\data_pulling\\dump_bin.py", line 500, in _dump_features\n    _future.result()\n  File "C:\\Users\\Ian\\anaconda3\\envs\\qlbt\\lib\\concurrent\\futures\\_base.py", line 437, in result\n    return self.__get_result()\n  File "C:\\Users\\Ian\\anaconda3\\envs\\qlbt\\lib\\concurrent\\futures\\_base.py", line 389, in __get_result\n    raise self._exception\n  File "C:\\Users\\Ian\\Documents\\Financial testing\\data_pulling\\dump_bin.py", line 500, in _dump_features\n    _future.result()\n  File "C:\\Users\\Ian\\anaconda3\\envs\\qlbt\\lib\\concurrent\\futures\\_base.py", line 437, in result\n    return self.__get_result()\n  File "C:\\Users\\Ian\\anaconda3\\envs\\qlbt\\lib\\concurrent\\futures\\_base.py", line 389, in __get_result\n    raise self._exception\n  File "C:\\Users\\Ian\\Documents\\Financial testing\\data_pulling\\dump_bin.py", line 500, in _dump_features\n    _future.result()\n  File "C:\\Users\\Ian\\anaconda3\\envs\\qlbt\\lib\\concurrent\\futures\\_base.py", line 437, in result\n    return self.__get_result()\n  File "C:\\Users\\Ian\\anaconda3\\envs\\qlbt\\lib\\concurrent\\futures\\_base.py", line 389, in __get_result\n    raise self._exception\n  File "C:\\Users\\Ian\\Documents\\Financial testing\\data_pulling\\dump_bin.py", line 500, in _dump_features\n    _future.result()\n  File "C:\\Users\\Ian\\anaconda3\\envs\\qlbt\\lib\\concurrent\\futures\\_base.py", line 437, in result\n    return self.__get_result()\n  File "C:\\Users\\Ian\\anaconda3\\envs\\qlbt\\lib\\concurrent\\futures\\_base.py", line 389, in __get_result\n    raise self._exception\nconcurrent.futures.process.BrokenProcessPool: A process in the process pool was terminated abruptly while the future was running or pending.\n', 'MATICBUSD': 'Traceback (most recent call last):\n  File "C:\\Users\\Ian\\Documents\\Financial testing\\data_pulling\\dump_bin.py", line 500, in _dump_features\n    _future.result()\n  File "C:\\Users\\Ian\\anaconda3\\envs\\qlbt\\lib\\concurrent\\futures\\_base.py", line 437, in result\n    return self.__get_result()\n  File "C:\\Users\\Ian\\anaconda3\\envs\\qlbt\\lib\\concurrent\\futures\\_base.py", line 389, in __get_result\n    raise self._exception\n  File "C:\\Users\\Ian\\Documents\\Financial testing\\data_pulling\\dump_bin.py", line 500, in _dump_features\n    _future.result()\n  File "C:\\Users\\Ian\\anaconda3\\envs\\qlbt\\lib\\concurrent\\futures\\_base.py", line 437, in result\n    return self.__get_result()\n  File "C:\\Users\\Ian\\anaconda3\\envs\\qlbt\\lib\\concurrent\\futures\\_base.py", line 389, in __get_result\n    raise self._exception\n  File "C:\\Users\\Ian\\Documents\\Financial testing\\data_pulling\\dump_bin.py", line 500, in _dump_features\n    _future.result()\n  File "C:\\Users\\Ian\\anaconda3\\envs\\qlbt\\lib\\concurrent\\futures\\_base.py", line 437, in result\n    return self.__get_result()\n  File "C:\\Users\\Ian\\anaconda3\\envs\\qlbt\\lib\\concurrent\\futures\\_base.py", line 389, in __get_result\n    raise self._exception\n  File "C:\\Users\\Ian\\Documents\\Financial testing\\data_pulling\\dump_bin.py", line 500, in _dump_features\n    _future.result()\n  File "C:\\Users\\Ian\\anaconda3\\envs\\qlbt\\lib\\concurrent\\futures\\_base.py", line 437, in result\n    return self.__get_result()\n  File "C:\\Users\\Ian\\anaconda3\\envs\\qlbt\\lib\\concurrent\\futures\\_base.py", line 389, in __get_result\n    raise self._exception\n  File "C:\\Users\\Ian\\Documents\\Financial testing\\data_pulling\\dump_bin.py", line 500, in _dump_features\n    _future.result()\n  File "C:\\Users\\Ian\\anaconda3\\envs\\qlbt\\lib\\concurrent\\futures\\_base.py", line 437, in result\n    return self.__get_result()\n  File "C:\\Users\\Ian\\anaconda3\\envs\\qlbt\\lib\\concurrent\\futures\\_base.py", line 389, in __get_result\n    raise self._exception\n  File "C:\\Users\\Ian\\Documents\\Financial testing\\data_pulling\\dump_bin.py", line 500, in _dump_features\n    _future.result()\n  File "C:\\Users\\Ian\\anaconda3\\envs\\qlbt\\lib\\concurrent\\futures\\_base.py", line 437, in result\n    return self.__get_result()\n  File "C:\\Users\\Ian\\anaconda3\\envs\\qlbt\\lib\\concurrent\\futures\\_base.py", line 389, in __get_result\n    raise self._exception\n  File "C:\\Users\\Ian\\Documents\\Financial testing\\data_pulling\\dump_bin.py", line 500, in _dump_features\n    _future.result()\n  File "C:\\Users\\Ian\\anaconda3\\envs\\qlbt\\lib\\concurrent\\futures\\_base.py", line 437, in result\n    return self.__get_result()\n  File "C:\\Users\\Ian\\anaconda3\\envs\\qlbt\\lib\\concurrent\\futures\\_base.py", line 389, in __get_result\n    raise self._exception\n  File "C:\\Users\\Ian\\Documents\\Financial testing\\data_pulling\\dump_bin.py", line 500, in _dump_features\n    _future.result()\n  File "C:\\Users\\Ian\\anaconda3\\envs\\qlbt\\lib\\concurrent\\futures\\_base.py", line 437, in result\n    return self.__get_result()\n  File "C:\\Users\\Ian\\anaconda3\\envs\\qlbt\\lib\\concurrent\\futures\\_base.py", line 389, in __get_result\n    raise self._exception\n  File "C:\\Users\\Ian\\Documents\\Financial testing\\data_pulling\\dump_bin.py", line 500, in _dump_features\n    _future.result()\n  File "C:\\Users\\Ian\\anaconda3\\envs\\qlbt\\lib\\concurrent\\futures\\_base.py", line 437, in result\n    return self.__get_result()\n  File "C:\\Users\\Ian\\anaconda3\\envs\\qlbt\\lib\\concurrent\\futures\\_base.py", line 389, in __get_result\n    raise self._exception\n  File "C:\\Users\\Ian\\Documents\\Financial testing\\data_pulling\\dump_bin.py", line 500, in _dump_features\n    _future.result()\n  File "C:\\Users\\Ian\\anaconda3\\envs\\qlbt\\lib\\concurrent\\futures\\_base.py", line 437, in result\n    return self.__get_result()\n  File "C:\\Users\\Ian\\anaconda3\\envs\\qlbt\\lib\\concurrent\\futures\\_base.py", line 389, in __get_result\n    raise self._exception\n  File "C:\\Users\\Ian\\Documents\\Financial testing\\data_pulling\\dump_bin.py", line 500, in _dump_features\n    _future.result()\n  File "C:\\Users\\Ian\\anaconda3\\envs\\qlbt\\lib\\concurrent\\futures\\_base.py", line 437, in result\n    return self.__get_result()\n  File "C:\\Users\\Ian\\anaconda3\\envs\\qlbt\\lib\\concurrent\\futures\\_base.py", line 389, in __get_result\n    raise self._exception\n  File "C:\\Users\\Ian\\Documents\\Financial testing\\data_pulling\\dump_bin.py", line 500, in _dump_features\n    _future.result()\n  File "C:\\Users\\Ian\\anaconda3\\envs\\qlbt\\lib\\concurrent\\futures\\_base.py", line 437, in result\n    return self.__get_result()\n  File "C:\\Users\\Ian\\anaconda3\\envs\\qlbt\\lib\\concurrent\\futures\\_base.py", line 389, in __get_result\n    raise self._exception\nconcurrent.futures.process.BrokenProcessPool: A process in the process pool was terminated abruptly while the future was running or pending.\n', 'NEARBUSD': 'Traceback (most recent call last):\n  File "C:\\Users\\Ian\\Documents\\Financial testing\\data_pulling\\dump_bin.py", line 500, in _dump_features\n    _future.result()\n  File "C:\\Users\\Ian\\anaconda3\\envs\\qlbt\\lib\\concurrent\\futures\\_base.py", line 437, in result\n    return self.__get_result()\n  File "C:\\Users\\Ian\\anaconda3\\envs\\qlbt\\lib\\concurrent\\futures\\_base.py", line 389, in __get_result\n    raise self._exception\n  File "C:\\Users\\Ian\\Documents\\Financial testing\\data_pulling\\dump_bin.py", line 500, in _dump_features\n    _future.result()\n  File "C:\\Users\\Ian\\anaconda3\\envs\\qlbt\\lib\\concurrent\\futures\\_base.py", line 437, in result\n    return self.__get_result()\n  File "C:\\Users\\Ian\\anaconda3\\envs\\qlbt\\lib\\concurrent\\futures\\_base.py", line 389, in __get_result\n    raise self._exception\n  File "C:\\Users\\Ian\\Documents\\Financial testing\\data_pulling\\dump_bin.py", line 500, in _dump_features\n    _future.result()\n  File "C:\\Users\\Ian\\anaconda3\\envs\\qlbt\\lib\\concurrent\\futures\\_base.py", line 437, in result\n    return self.__get_result()\n  File "C:\\Users\\Ian\\anaconda3\\envs\\qlbt\\lib\\concurrent\\futures\\_base.py", line 389, in __get_result\n    raise self._exception\n  File "C:\\Users\\Ian\\Documents\\Financial testing\\data_pulling\\dump_bin.py", line 500, in _dump_features\n    _future.result()\n  File "C:\\Users\\Ian\\anaconda3\\envs\\qlbt\\lib\\concurrent\\futures\\_base.py", line 437, in result\n    return self.__get_result()\n  File "C:\\Users\\Ian\\anaconda3\\envs\\qlbt\\lib\\concurrent\\futures\\_base.py", line 389, in __get_result\n    raise self._exception\n  File "C:\\Users\\Ian\\Documents\\Financial testing\\data_pulling\\dump_bin.py", line 500, in _dump_features\n    _future.result()\n  File "C:\\Users\\Ian\\anaconda3\\envs\\qlbt\\lib\\concurrent\\futures\\_base.py", line 437, in result\n    return self.__get_result()\n  File "C:\\Users\\Ian\\anaconda3\\envs\\qlbt\\lib\\concurrent\\futures\\_base.py", line 389, in __get_result\n    raise self._exception\n  File "C:\\Users\\Ian\\Documents\\Financial testing\\data_pulling\\dump_bin.py", line 500, in _dump_features\n    _future.result()\n  File "C:\\Users\\Ian\\anaconda3\\envs\\qlbt\\lib\\concurrent\\futures\\_base.py", line 437, in result\n    return self.__get_result()\n  File "C:\\Users\\Ian\\anaconda3\\envs\\qlbt\\lib\\concurrent\\futures\\_base.py", line 389, in __get_result\n    raise self._exception\n  File "C:\\Users\\Ian\\Documents\\Financial testing\\data_pulling\\dump_bin.py", line 500, in _dump_features\n    _future.result()\n  File "C:\\Users\\Ian\\anaconda3\\envs\\qlbt\\lib\\concurrent\\futures\\_base.py", line 437, in result\n    return self.__get_result()\n  File "C:\\Users\\Ian\\anaconda3\\envs\\qlbt\\lib\\concurrent\\futures\\_base.py", line 389, in __get_result\n    raise self._exception\n  File "C:\\Users\\Ian\\Documents\\Financial testing\\data_pulling\\dump_bin.py", line 500, in _dump_features\n    _future.result()\n  File "C:\\Users\\Ian\\anaconda3\\envs\\qlbt\\lib\\concurrent\\futures\\_base.py", line 437, in result\n    return self.__get_result()\n  File "C:\\Users\\Ian\\anaconda3\\envs\\qlbt\\lib\\concurrent\\futures\\_base.py", line 389, in __get_result\n    raise self._exception\n  File "C:\\Users\\Ian\\Documents\\Financial testing\\data_pulling\\dump_bin.py", line 500, in _dump_features\n    _future.result()\n  File "C:\\Users\\Ian\\anaconda3\\envs\\qlbt\\lib\\concurrent\\futures\\_base.py", line 437, in result\n    return self.__get_result()\n  File "C:\\Users\\Ian\\anaconda3\\envs\\qlbt\\lib\\concurrent\\futures\\_base.py", line 389, in __get_result\n    raise self._exception\n  File "C:\\Users\\Ian\\Documents\\Financial testing\\data_pulling\\dump_bin.py", line 500, in _dump_features\n    _future.result()\n  File "C:\\Users\\Ian\\anaconda3\\envs\\qlbt\\lib\\concurrent\\futures\\_base.py", line 437, in result\n    return self.__get_result()\n  File "C:\\Users\\Ian\\anaconda3\\envs\\qlbt\\lib\\concurrent\\futures\\_base.py", line 389, in __get_result\n    raise self._exception\n  File "C:\\Users\\Ian\\Documents\\Financial testing\\data_pulling\\dump_bin.py", line 500, in _dump_features\n    _future.result()\n  File "C:\\Users\\Ian\\anaconda3\\envs\\qlbt\\lib\\concurrent\\futures\\_base.py", line 437, in result\n    return self.__get_result()\n  File "C:\\Users\\Ian\\anaconda3\\envs\\qlbt\\lib\\concurrent\\futures\\_base.py", line 389, in __get_result\n    raise self._exception\n  File "C:\\Users\\Ian\\Documents\\Financial testing\\data_pulling\\dump_bin.py", line 500, in _dump_features\n    _future.result()\n  File "C:\\Users\\Ian\\anaconda3\\envs\\qlbt\\lib\\concurrent\\futures\\_base.py", line 437, in result\n    return self.__get_result()\n  File "C:\\Users\\Ian\\anaconda3\\envs\\qlbt\\lib\\concurrent\\futures\\_base.py", line 389, in __get_result\n    raise self._exception\n  File "C:\\Users\\Ian\\Documents\\Financial testing\\data_pulling\\dump_bin.py", line 500, in _dump_features\n    _future.result()\n  File "C:\\Users\\Ian\\anaconda3\\envs\\qlbt\\lib\\concurrent\\futures\\_base.py", line 437, in result\n    return self.__get_result()\n  File "C:\\Users\\Ian\\anaconda3\\envs\\qlbt\\lib\\concurrent\\futures\\_base.py", line 389, in __get_result\n    raise self._exception\nconcurrent.futures.process.BrokenProcessPool: A process in the process pool was terminated abruptly while the future was running or pending.\n', 'OPBUSD': 'Traceback (most recent call last):\n  File "C:\\Users\\Ian\\Documents\\Financial testing\\data_pulling\\dump_bin.py", line 500, in _dump_features\n    _future.result()\n  File "C:\\Users\\Ian\\anaconda3\\envs\\qlbt\\lib\\concurrent\\futures\\_base.py", line 437, in result\n    return self.__get_result()\n  File "C:\\Users\\Ian\\anaconda3\\envs\\qlbt\\lib\\concurrent\\futures\\_base.py", line 389, in __get_result\n    raise self._exception\n  File "C:\\Users\\Ian\\Documents\\Financial testing\\data_pulling\\dump_bin.py", line 500, in _dump_features\n    _future.result()\n  File "C:\\Users\\Ian\\anaconda3\\envs\\qlbt\\lib\\concurrent\\futures\\_base.py", line 437, in result\n    return self.__get_result()\n  File "C:\\Users\\Ian\\anaconda3\\envs\\qlbt\\lib\\concurrent\\futures\\_base.py", line 389, in __get_result\n    raise self._exception\n  File "C:\\Users\\Ian\\Documents\\Financial testing\\data_pulling\\dump_bin.py", line 500, in _dump_features\n    _future.result()\n  File "C:\\Users\\Ian\\anaconda3\\envs\\qlbt\\lib\\concurrent\\futures\\_base.py", line 437, in result\n    return self.__get_result()\n  File "C:\\Users\\Ian\\anaconda3\\envs\\qlbt\\lib\\concurrent\\futures\\_base.py", line 389, in __get_result\n    raise self._exception\n  File "C:\\Users\\Ian\\Documents\\Financial testing\\data_pulling\\dump_bin.py", line 500, in _dump_features\n    _future.result()\n  File "C:\\Users\\Ian\\anaconda3\\envs\\qlbt\\lib\\concurrent\\futures\\_base.py", line 437, in result\n    return self.__get_result()\n  File "C:\\Users\\Ian\\anaconda3\\envs\\qlbt\\lib\\concurrent\\futures\\_base.py", line 389, in __get_result\n    raise self._exception\n  File "C:\\Users\\Ian\\Documents\\Financial testing\\data_pulling\\dump_bin.py", line 500, in _dump_features\n    _future.result()\n  File "C:\\Users\\Ian\\anaconda3\\envs\\qlbt\\lib\\concurrent\\futures\\_base.py", line 437, in result\n    return self.__get_result()\n  File "C:\\Users\\Ian\\anaconda3\\envs\\qlbt\\lib\\concurrent\\futures\\_base.py", line 389, in __get_result\n    raise self._exception\n  File "C:\\Users\\Ian\\Documents\\Financial testing\\data_pulling\\dump_bin.py", line 500, in _dump_features\n    _future.result()\n  File "C:\\Users\\Ian\\anaconda3\\envs\\qlbt\\lib\\concurrent\\futures\\_base.py", line 437, in result\n    return self.__get_result()\n  File "C:\\Users\\Ian\\anaconda3\\envs\\qlbt\\lib\\concurrent\\futures\\_base.py", line 389, in __get_result\n    raise self._exception\n  File "C:\\Users\\Ian\\Documents\\Financial testing\\data_pulling\\dump_bin.py", line 500, in _dump_features\n    _future.result()\n  File "C:\\Users\\Ian\\anaconda3\\envs\\qlbt\\lib\\concurrent\\futures\\_base.py", line 437, in result\n    return self.__get_result()\n  File "C:\\Users\\Ian\\anaconda3\\envs\\qlbt\\lib\\concurrent\\futures\\_base.py", line 389, in __get_result\n    raise self._exception\n  File "C:\\Users\\Ian\\Documents\\Financial testing\\data_pulling\\dump_bin.py", line 500, in _dump_features\n    _future.result()\n  File "C:\\Users\\Ian\\anaconda3\\envs\\qlbt\\lib\\concurrent\\futures\\_base.py", line 437, in result\n    return self.__get_result()\n  File "C:\\Users\\Ian\\anaconda3\\envs\\qlbt\\lib\\concurrent\\futures\\_base.py", line 389, in __get_result\n    raise self._exception\n  File "C:\\Users\\Ian\\Documents\\Financial testing\\data_pulling\\dump_bin.py", line 500, in _dump_features\n    _future.result()\n  File "C:\\Users\\Ian\\anaconda3\\envs\\qlbt\\lib\\concurrent\\futures\\_base.py", line 437, in result\n    return self.__get_result()\n  File "C:\\Users\\Ian\\anaconda3\\envs\\qlbt\\lib\\concurrent\\futures\\_base.py", line 389, in __get_result\n    raise self._exception\n  File "C:\\Users\\Ian\\Documents\\Financial testing\\data_pulling\\dump_bin.py", line 500, in _dump_features\n    _future.result()\n  File "C:\\Users\\Ian\\anaconda3\\envs\\qlbt\\lib\\concurrent\\futures\\_base.py", line 437, in result\n    return self.__get_result()\n  File "C:\\Users\\Ian\\anaconda3\\envs\\qlbt\\lib\\concurrent\\futures\\_base.py", line 389, in __get_result\n    raise self._exception\n  File "C:\\Users\\Ian\\Documents\\Financial testing\\data_pulling\\dump_bin.py", line 500, in _dump_features\n    _future.result()\n  File "C:\\Users\\Ian\\anaconda3\\envs\\qlbt\\lib\\concurrent\\futures\\_base.py", line 437, in result\n    return self.__get_result()\n  File "C:\\Users\\Ian\\anaconda3\\envs\\qlbt\\lib\\concurrent\\futures\\_base.py", line 389, in __get_result\n    raise self._exception\n  File "C:\\Users\\Ian\\Documents\\Financial testing\\data_pulling\\dump_bin.py", line 500, in _dump_features\n    _future.result()\n  File "C:\\Users\\Ian\\anaconda3\\envs\\qlbt\\lib\\concurrent\\futures\\_base.py", line 437, in result\n    return self.__get_result()\n  File "C:\\Users\\Ian\\anaconda3\\envs\\qlbt\\lib\\concurrent\\futures\\_base.py", line 389, in __get_result\n    raise self._exception\n  File "C:\\Users\\Ian\\Documents\\Financial testing\\data_pulling\\dump_bin.py", line 500, in _dump_features\n    _future.result()\n  File "C:\\Users\\Ian\\anaconda3\\envs\\qlbt\\lib\\concurrent\\futures\\_base.py", line 437, in result\n    return self.__get_result()\n  File "C:\\Users\\Ian\\anaconda3\\envs\\qlbt\\lib\\concurrent\\futures\\_base.py", line 389, in __get_result\n    raise self._exception\n  File "C:\\Users\\Ian\\Documents\\Financial testing\\data_pulling\\dump_bin.py", line 500, in _dump_features\n    _future.result()\n  File "C:\\Users\\Ian\\anaconda3\\envs\\qlbt\\lib\\concurrent\\futures\\_base.py", line 437, in result\n    return self.__get_result()\n  File "C:\\Users\\Ian\\anaconda3\\envs\\qlbt\\lib\\concurrent\\futures\\_base.py", line 389, in __get_result\n    raise self._exception\nconcurrent.futures.process.BrokenProcessPool: A process in the process pool was terminated abruptly while the future was running or pending.\n', 'SOLBUSD': 'Traceback (most recent call last):\n  File "C:\\Users\\Ian\\Documents\\Financial testing\\data_pulling\\dump_bin.py", line 500, in _dump_features\n    _future.result()\n  File "C:\\Users\\Ian\\anaconda3\\envs\\qlbt\\lib\\concurrent\\futures\\_base.py", line 437, in result\n    return self.__get_result()\n  File "C:\\Users\\Ian\\anaconda3\\envs\\qlbt\\lib\\concurrent\\futures\\_base.py", line 389, in __get_result\n    raise self._exception\n  File "C:\\Users\\Ian\\Documents\\Financial testing\\data_pulling\\dump_bin.py", line 500, in _dump_features\n    _future.result()\n  File "C:\\Users\\Ian\\anaconda3\\envs\\qlbt\\lib\\concurrent\\futures\\_base.py", line 437, in result\n    return self.__get_result()\n  File "C:\\Users\\Ian\\anaconda3\\envs\\qlbt\\lib\\concurrent\\futures\\_base.py", line 389, in __get_result\n    raise self._exception\n  File "C:\\Users\\Ian\\Documents\\Financial testing\\data_pulling\\dump_bin.py", line 500, in _dump_features\n    _future.result()\n  File "C:\\Users\\Ian\\anaconda3\\envs\\qlbt\\lib\\concurrent\\futures\\_base.py", line 437, in result\n    return self.__get_result()\n  File "C:\\Users\\Ian\\anaconda3\\envs\\qlbt\\lib\\concurrent\\futures\\_base.py", line 389, in __get_result\n    raise self._exception\n  File "C:\\Users\\Ian\\Documents\\Financial testing\\data_pulling\\dump_bin.py", line 500, in _dump_features\n    _future.result()\n  File "C:\\Users\\Ian\\anaconda3\\envs\\qlbt\\lib\\concurrent\\futures\\_base.py", line 437, in result\n    return self.__get_result()\n  File "C:\\Users\\Ian\\anaconda3\\envs\\qlbt\\lib\\concurrent\\futures\\_base.py", line 389, in __get_result\n    raise self._exception\n  File "C:\\Users\\Ian\\Documents\\Financial testing\\data_pulling\\dump_bin.py", line 500, in _dump_features\n    _future.result()\n  File "C:\\Users\\Ian\\anaconda3\\envs\\qlbt\\lib\\concurrent\\futures\\_base.py", line 437, in result\n    return self.__get_result()\n  File "C:\\Users\\Ian\\anaconda3\\envs\\qlbt\\lib\\concurrent\\futures\\_base.py", line 389, in __get_result\n    raise self._exception\n  File "C:\\Users\\Ian\\Documents\\Financial testing\\data_pulling\\dump_bin.py", line 500, in _dump_features\n    _future.result()\n  File "C:\\Users\\Ian\\anaconda3\\envs\\qlbt\\lib\\concurrent\\futures\\_base.py", line 437, in result\n    return self.__get_result()\n  File "C:\\Users\\Ian\\anaconda3\\envs\\qlbt\\lib\\concurrent\\futures\\_base.py", line 389, in __get_result\n    raise self._exception\n  File "C:\\Users\\Ian\\Documents\\Financial testing\\data_pulling\\dump_bin.py", line 500, in _dump_features\n    _future.result()\n  File "C:\\Users\\Ian\\anaconda3\\envs\\qlbt\\lib\\concurrent\\futures\\_base.py", line 437, in result\n    return self.__get_result()\n  File "C:\\Users\\Ian\\anaconda3\\envs\\qlbt\\lib\\concurrent\\futures\\_base.py", line 389, in __get_result\n    raise self._exception\n  File "C:\\Users\\Ian\\Documents\\Financial testing\\data_pulling\\dump_bin.py", line 500, in _dump_features\n    _future.result()\n  File "C:\\Users\\Ian\\anaconda3\\envs\\qlbt\\lib\\concurrent\\futures\\_base.py", line 437, in result\n    return self.__get_result()\n  File "C:\\Users\\Ian\\anaconda3\\envs\\qlbt\\lib\\concurrent\\futures\\_base.py", line 389, in __get_result\n    raise self._exception\n  File "C:\\Users\\Ian\\Documents\\Financial testing\\data_pulling\\dump_bin.py", line 500, in _dump_features\n    _future.result()\n  File "C:\\Users\\Ian\\anaconda3\\envs\\qlbt\\lib\\concurrent\\futures\\_base.py", line 437, in result\n    return self.__get_result()\n  File "C:\\Users\\Ian\\anaconda3\\envs\\qlbt\\lib\\concurrent\\futures\\_base.py", line 389, in __get_result\n    raise self._exception\n  File "C:\\Users\\Ian\\Documents\\Financial testing\\data_pulling\\dump_bin.py", line 500, in _dump_features\n    _future.result()\n  File "C:\\Users\\Ian\\anaconda3\\envs\\qlbt\\lib\\concurrent\\futures\\_base.py", line 437, in result\n    return self.__get_result()\n  File "C:\\Users\\Ian\\anaconda3\\envs\\qlbt\\lib\\concurrent\\futures\\_base.py", line 389, in __get_result\n    raise self._exception\n  File "C:\\Users\\Ian\\Documents\\Financial testing\\data_pulling\\dump_bin.py", line 500, in _dump_features\n    _future.result()\n  File "C:\\Users\\Ian\\anaconda3\\envs\\qlbt\\lib\\concurrent\\futures\\_base.py", line 437, in result\n    return self.__get_result()\n  File "C:\\Users\\Ian\\anaconda3\\envs\\qlbt\\lib\\concurrent\\futures\\_base.py", line 389, in __get_result\n    raise self._exception\n  File "C:\\Users\\Ian\\Documents\\Financial testing\\data_pulling\\dump_bin.py", line 500, in _dump_features\n    _future.result()\n  File "C:\\Users\\Ian\\anaconda3\\envs\\qlbt\\lib\\concurrent\\futures\\_base.py", line 437, in result\n    return self.__get_result()\n  File "C:\\Users\\Ian\\anaconda3\\envs\\qlbt\\lib\\concurrent\\futures\\_base.py", line 389, in __get_result\n    raise self._exception\n  File "C:\\Users\\Ian\\Documents\\Financial testing\\data_pulling\\dump_bin.py", line 500, in _dump_features\n    _future.result()\n  File "C:\\Users\\Ian\\anaconda3\\envs\\qlbt\\lib\\concurrent\\futures\\_base.py", line 437, in result\n    return self.__get_result()\n  File "C:\\Users\\Ian\\anaconda3\\envs\\qlbt\\lib\\concurrent\\futures\\_base.py", line 389, in __get_result\n    raise self._exception\n  File "C:\\Users\\Ian\\Documents\\Financial testing\\data_pulling\\dump_bin.py", line 500, in _dump_features\n    _future.result()\n  File "C:\\Users\\Ian\\anaconda3\\envs\\qlbt\\lib\\concurrent\\futures\\_base.py", line 437, in result\n    return self.__get_result()\n  File "C:\\Users\\Ian\\anaconda3\\envs\\qlbt\\lib\\concurrent\\futures\\_base.py", line 389, in __get_result\n    raise self._exception\n  File "C:\\Users\\Ian\\Documents\\Financial testing\\data_pulling\\dump_bin.py", line 500, in _dump_features\n    _future.result()\n  File "C:\\Users\\Ian\\anaconda3\\envs\\qlbt\\lib\\concurrent\\futures\\_base.py", line 437, in result\n    return self.__get_result()\n  File "C:\\Users\\Ian\\anaconda3\\envs\\qlbt\\lib\\concurrent\\futures\\_base.py", line 389, in __get_result\n    raise self._exception\nconcurrent.futures.process.BrokenProcessPool: A process in the process pool was terminated abruptly while the future was running or pending.\n', 'TRXBUSD': 'Traceback (most recent call last):\n  File "C:\\Users\\Ian\\Documents\\Financial testing\\data_pulling\\dump_bin.py", line 500, in _dump_features\n    _future.result()\n  File "C:\\Users\\Ian\\anaconda3\\envs\\qlbt\\lib\\concurrent\\futures\\_base.py", line 437, in result\n    return self.__get_result()\n  File "C:\\Users\\Ian\\anaconda3\\envs\\qlbt\\lib\\concurrent\\futures\\_base.py", line 389, in __get_result\n    raise self._exception\n  File "C:\\Users\\Ian\\Documents\\Financial testing\\data_pulling\\dump_bin.py", line 500, in _dump_features\n    _future.result()\n  File "C:\\Users\\Ian\\anaconda3\\envs\\qlbt\\lib\\concurrent\\futures\\_base.py", line 437, in result\n    return self.__get_result()\n  File "C:\\Users\\Ian\\anaconda3\\envs\\qlbt\\lib\\concurrent\\futures\\_base.py", line 389, in __get_result\n    raise self._exception\n  File "C:\\Users\\Ian\\Documents\\Financial testing\\data_pulling\\dump_bin.py", line 500, in _dump_features\n    _future.result()\n  File "C:\\Users\\Ian\\anaconda3\\envs\\qlbt\\lib\\concurrent\\futures\\_base.py", line 437, in result\n    return self.__get_result()\n  File "C:\\Users\\Ian\\anaconda3\\envs\\qlbt\\lib\\concurrent\\futures\\_base.py", line 389, in __get_result\n    raise self._exception\n  File "C:\\Users\\Ian\\Documents\\Financial testing\\data_pulling\\dump_bin.py", line 500, in _dump_features\n    _future.result()\n  File "C:\\Users\\Ian\\anaconda3\\envs\\qlbt\\lib\\concurrent\\futures\\_base.py", line 437, in result\n    return self.__get_result()\n  File "C:\\Users\\Ian\\anaconda3\\envs\\qlbt\\lib\\concurrent\\futures\\_base.py", line 389, in __get_result\n    raise self._exception\n  File "C:\\Users\\Ian\\Documents\\Financial testing\\data_pulling\\dump_bin.py", line 500, in _dump_features\n    _future.result()\n  File "C:\\Users\\Ian\\anaconda3\\envs\\qlbt\\lib\\concurrent\\futures\\_base.py", line 437, in result\n    return self.__get_result()\n  File "C:\\Users\\Ian\\anaconda3\\envs\\qlbt\\lib\\concurrent\\futures\\_base.py", line 389, in __get_result\n    raise self._exception\n  File "C:\\Users\\Ian\\Documents\\Financial testing\\data_pulling\\dump_bin.py", line 500, in _dump_features\n    _future.result()\n  File "C:\\Users\\Ian\\anaconda3\\envs\\qlbt\\lib\\concurrent\\futures\\_base.py", line 437, in result\n    return self.__get_result()\n  File "C:\\Users\\Ian\\anaconda3\\envs\\qlbt\\lib\\concurrent\\futures\\_base.py", line 389, in __get_result\n    raise self._exception\n  File "C:\\Users\\Ian\\Documents\\Financial testing\\data_pulling\\dump_bin.py", line 500, in _dump_features\n    _future.result()\n  File "C:\\Users\\Ian\\anaconda3\\envs\\qlbt\\lib\\concurrent\\futures\\_base.py", line 437, in result\n    return self.__get_result()\n  File "C:\\Users\\Ian\\anaconda3\\envs\\qlbt\\lib\\concurrent\\futures\\_base.py", line 389, in __get_result\n    raise self._exception\n  File "C:\\Users\\Ian\\Documents\\Financial testing\\data_pulling\\dump_bin.py", line 500, in _dump_features\n    _future.result()\n  File "C:\\Users\\Ian\\anaconda3\\envs\\qlbt\\lib\\concurrent\\futures\\_base.py", line 437, in result\n    return self.__get_result()\n  File "C:\\Users\\Ian\\anaconda3\\envs\\qlbt\\lib\\concurrent\\futures\\_base.py", line 389, in __get_result\n    raise self._exception\n  File "C:\\Users\\Ian\\Documents\\Financial testing\\data_pulling\\dump_bin.py", line 500, in _dump_features\n    _future.result()\n  File "C:\\Users\\Ian\\anaconda3\\envs\\qlbt\\lib\\concurrent\\futures\\_base.py", line 437, in result\n    return self.__get_result()\n  File "C:\\Users\\Ian\\anaconda3\\envs\\qlbt\\lib\\concurrent\\futures\\_base.py", line 389, in __get_result\n    raise self._exception\n  File "C:\\Users\\Ian\\Documents\\Financial testing\\data_pulling\\dump_bin.py", line 500, in _dump_features\n    _future.result()\n  File "C:\\Users\\Ian\\anaconda3\\envs\\qlbt\\lib\\concurrent\\futures\\_base.py", line 437, in result\n    return self.__get_result()\n  File "C:\\Users\\Ian\\anaconda3\\envs\\qlbt\\lib\\concurrent\\futures\\_base.py", line 389, in __get_result\n    raise self._exception\n  File "C:\\Users\\Ian\\Documents\\Financial testing\\data_pulling\\dump_bin.py", line 500, in _dump_features\n    _future.result()\n  File "C:\\Users\\Ian\\anaconda3\\envs\\qlbt\\lib\\concurrent\\futures\\_base.py", line 437, in result\n    return self.__get_result()\n  File "C:\\Users\\Ian\\anaconda3\\envs\\qlbt\\lib\\concurrent\\futures\\_base.py", line 389, in __get_result\n    raise self._exception\n  File "C:\\Users\\Ian\\Documents\\Financial testing\\data_pulling\\dump_bin.py", line 500, in _dump_features\n    _future.result()\n  File "C:\\Users\\Ian\\anaconda3\\envs\\qlbt\\lib\\concurrent\\futures\\_base.py", line 437, in result\n    return self.__get_result()\n  File "C:\\Users\\Ian\\anaconda3\\envs\\qlbt\\lib\\concurrent\\futures\\_base.py", line 389, in __get_result\n    raise self._exception\n  File "C:\\Users\\Ian\\Documents\\Financial testing\\data_pulling\\dump_bin.py", line 500, in _dump_features\n    _future.result()\n  File "C:\\Users\\Ian\\anaconda3\\envs\\qlbt\\lib\\concurrent\\futures\\_base.py", line 437, in result\n    return self.__get_result()\n  File "C:\\Users\\Ian\\anaconda3\\envs\\qlbt\\lib\\concurrent\\futures\\_base.py", line 389, in __get_result\n    raise self._exception\n  File "C:\\Users\\Ian\\Documents\\Financial testing\\data_pulling\\dump_bin.py", line 500, in _dump_features\n    _future.result()\n  File "C:\\Users\\Ian\\anaconda3\\envs\\qlbt\\lib\\concurrent\\futures\\_base.py", line 437, in result\n    return self.__get_result()\n  File "C:\\Users\\Ian\\anaconda3\\envs\\qlbt\\lib\\concurrent\\futures\\_base.py", line 389, in __get_result\n    raise self._exception\n  File "C:\\Users\\Ian\\Documents\\Financial testing\\data_pulling\\dump_bin.py", line 500, in _dump_features\n    _future.result()\n  File "C:\\Users\\Ian\\anaconda3\\envs\\qlbt\\lib\\concurrent\\futures\\_base.py", line 437, in result\n    return self.__get_result()\n  File "C:\\Users\\Ian\\anaconda3\\envs\\qlbt\\lib\\concurrent\\futures\\_base.py", line 389, in __get_result\n    raise self._exception\n  File "C:\\Users\\Ian\\Documents\\Financial testing\\data_pulling\\dump_bin.py", line 500, in _dump_features\n    _future.result()\n  File "C:\\Users\\Ian\\anaconda3\\envs\\qlbt\\lib\\concurrent\\futures\\_base.py", line 437, in result\n    return self.__get_result()\n  File "C:\\Users\\Ian\\anaconda3\\envs\\qlbt\\lib\\concurrent\\futures\\_base.py", line 389, in __get_result\n    raise self._exception\nconcurrent.futures.process.BrokenProcessPool: A process in the process pool was terminated abruptly while the future was running or pending.\n', 'VETBUSD': 'Traceback (most recent call last):\n  File "C:\\Users\\Ian\\Documents\\Financial testing\\data_pulling\\dump_bin.py", line 500, in _dump_features\n    _future.result()\n  File "C:\\Users\\Ian\\anaconda3\\envs\\qlbt\\lib\\concurrent\\futures\\_base.py", line 437, in result\n    return self.__get_result()\n  File "C:\\Users\\Ian\\anaconda3\\envs\\qlbt\\lib\\concurrent\\futures\\_base.py", line 389, in __get_result\n    raise self._exception\n  File "C:\\Users\\Ian\\Documents\\Financial testing\\data_pulling\\dump_bin.py", line 500, in _dump_features\n    _future.result()\n  File "C:\\Users\\Ian\\anaconda3\\envs\\qlbt\\lib\\concurrent\\futures\\_base.py", line 437, in result\n    return self.__get_result()\n  File "C:\\Users\\Ian\\anaconda3\\envs\\qlbt\\lib\\concurrent\\futures\\_base.py", line 389, in __get_result\n    raise self._exception\n  File "C:\\Users\\Ian\\Documents\\Financial testing\\data_pulling\\dump_bin.py", line 500, in _dump_features\n    _future.result()\n  File "C:\\Users\\Ian\\anaconda3\\envs\\qlbt\\lib\\concurrent\\futures\\_base.py", line 437, in result\n    return self.__get_result()\n  File "C:\\Users\\Ian\\anaconda3\\envs\\qlbt\\lib\\concurrent\\futures\\_base.py", line 389, in __get_result\n    raise self._exception\n  File "C:\\Users\\Ian\\Documents\\Financial testing\\data_pulling\\dump_bin.py", line 500, in _dump_features\n    _future.result()\n  File "C:\\Users\\Ian\\anaconda3\\envs\\qlbt\\lib\\concurrent\\futures\\_base.py", line 437, in result\n    return self.__get_result()\n  File "C:\\Users\\Ian\\anaconda3\\envs\\qlbt\\lib\\concurrent\\futures\\_base.py", line 389, in __get_result\n    raise self._exception\n  File "C:\\Users\\Ian\\Documents\\Financial testing\\data_pulling\\dump_bin.py", line 500, in _dump_features\n    _future.result()\n  File "C:\\Users\\Ian\\anaconda3\\envs\\qlbt\\lib\\concurrent\\futures\\_base.py", line 437, in result\n    return self.__get_result()\n  File "C:\\Users\\Ian\\anaconda3\\envs\\qlbt\\lib\\concurrent\\futures\\_base.py", line 389, in __get_result\n    raise self._exception\n  File "C:\\Users\\Ian\\Documents\\Financial testing\\data_pulling\\dump_bin.py", line 500, in _dump_features\n    _future.result()\n  File "C:\\Users\\Ian\\anaconda3\\envs\\qlbt\\lib\\concurrent\\futures\\_base.py", line 437, in result\n    return self.__get_result()\n  File "C:\\Users\\Ian\\anaconda3\\envs\\qlbt\\lib\\concurrent\\futures\\_base.py", line 389, in __get_result\n    raise self._exception\n  File "C:\\Users\\Ian\\Documents\\Financial testing\\data_pulling\\dump_bin.py", line 500, in _dump_features\n    _future.result()\n  File "C:\\Users\\Ian\\anaconda3\\envs\\qlbt\\lib\\concurrent\\futures\\_base.py", line 437, in result\n    return self.__get_result()\n  File "C:\\Users\\Ian\\anaconda3\\envs\\qlbt\\lib\\concurrent\\futures\\_base.py", line 389, in __get_result\n    raise self._exception\n  File "C:\\Users\\Ian\\Documents\\Financial testing\\data_pulling\\dump_bin.py", line 500, in _dump_features\n    _future.result()\n  File "C:\\Users\\Ian\\anaconda3\\envs\\qlbt\\lib\\concurrent\\futures\\_base.py", line 437, in result\n    return self.__get_result()\n  File "C:\\Users\\Ian\\anaconda3\\envs\\qlbt\\lib\\concurrent\\futures\\_base.py", line 389, in __get_result\n    raise self._exception\n  File "C:\\Users\\Ian\\Documents\\Financial testing\\data_pulling\\dump_bin.py", line 500, in _dump_features\n    _future.result()\n  File "C:\\Users\\Ian\\anaconda3\\envs\\qlbt\\lib\\concurrent\\futures\\_base.py", line 437, in result\n    return self.__get_result()\n  File "C:\\Users\\Ian\\anaconda3\\envs\\qlbt\\lib\\concurrent\\futures\\_base.py", line 389, in __get_result\n    raise self._exception\n  File "C:\\Users\\Ian\\Documents\\Financial testing\\data_pulling\\dump_bin.py", line 500, in _dump_features\n    _future.result()\n  File "C:\\Users\\Ian\\anaconda3\\envs\\qlbt\\lib\\concurrent\\futures\\_base.py", line 437, in result\n    return self.__get_result()\n  File "C:\\Users\\Ian\\anaconda3\\envs\\qlbt\\lib\\concurrent\\futures\\_base.py", line 389, in __get_result\n    raise self._exception\n  File "C:\\Users\\Ian\\Documents\\Financial testing\\data_pulling\\dump_bin.py", line 500, in _dump_features\n    _future.result()\n  File "C:\\Users\\Ian\\anaconda3\\envs\\qlbt\\lib\\concurrent\\futures\\_base.py", line 437, in result\n    return self.__get_result()\n  File "C:\\Users\\Ian\\anaconda3\\envs\\qlbt\\lib\\concurrent\\futures\\_base.py", line 389, in __get_result\n    raise self._exception\n  File "C:\\Users\\Ian\\Documents\\Financial testing\\data_pulling\\dump_bin.py", line 500, in _dump_features\n    _future.result()\n  File "C:\\Users\\Ian\\anaconda3\\envs\\qlbt\\lib\\concurrent\\futures\\_base.py", line 437, in result\n    return self.__get_result()\n  File "C:\\Users\\Ian\\anaconda3\\envs\\qlbt\\lib\\concurrent\\futures\\_base.py", line 389, in __get_result\n    raise self._exception\n  File "C:\\Users\\Ian\\Documents\\Financial testing\\data_pulling\\dump_bin.py", line 500, in _dump_features\n    _future.result()\n  File "C:\\Users\\Ian\\anaconda3\\envs\\qlbt\\lib\\concurrent\\futures\\_base.py", line 437, in result\n    return self.__get_result()\n  File "C:\\Users\\Ian\\anaconda3\\envs\\qlbt\\lib\\concurrent\\futures\\_base.py", line 389, in __get_result\n    raise self._exception\n  File "C:\\Users\\Ian\\Documents\\Financial testing\\data_pulling\\dump_bin.py", line 500, in _dump_features\n    _future.result()\n  File "C:\\Users\\Ian\\anaconda3\\envs\\qlbt\\lib\\concurrent\\futures\\_base.py", line 437, in result\n    return self.__get_result()\n  File "C:\\Users\\Ian\\anaconda3\\envs\\qlbt\\lib\\concurrent\\futures\\_base.py", line 389, in __get_result\n    raise self._exception\n  File "C:\\Users\\Ian\\Documents\\Financial testing\\data_pulling\\dump_bin.py", line 500, in _dump_features\n    _future.result()\n  File "C:\\Users\\Ian\\anaconda3\\envs\\qlbt\\lib\\concurrent\\futures\\_base.py", line 437, in result\n    return self.__get_result()\n  File "C:\\Users\\Ian\\anaconda3\\envs\\qlbt\\lib\\concurrent\\futures\\_base.py", line 389, in __get_result\n    raise self._exception\n  File "C:\\Users\\Ian\\Documents\\Financial testing\\data_pulling\\dump_bin.py", line 500, in _dump_features\n    _future.result()\n  File "C:\\Users\\Ian\\anaconda3\\envs\\qlbt\\lib\\concurrent\\futures\\_base.py", line 437, in result\n    return self.__get_result()\n  File "C:\\Users\\Ian\\anaconda3\\envs\\qlbt\\lib\\concurrent\\futures\\_base.py", line 389, in __get_result\n    raise self._exception\n  File "C:\\Users\\Ian\\Documents\\Financial testing\\data_pulling\\dump_bin.py", line 500, in _dump_features\n    _future.result()\n  File "C:\\Users\\Ian\\anaconda3\\envs\\qlbt\\lib\\concurrent\\futures\\_base.py", line 437, in result\n    return self.__get_result()\n  File "C:\\Users\\Ian\\anaconda3\\envs\\qlbt\\lib\\concurrent\\futures\\_base.py", line 389, in __get_result\n    raise self._exception\nconcurrent.futures.process.BrokenProcessPool: A process in the process pool was terminated abruptly while the future was running or pending.\n', 'WAVESBUSD': 'Traceback (most recent call last):\n  File "C:\\Users\\Ian\\Documents\\Financial testing\\data_pulling\\dump_bin.py", line 500, in _dump_features\n    _future.result()\n  File "C:\\Users\\Ian\\anaconda3\\envs\\qlbt\\lib\\concurrent\\futures\\_base.py", line 437, in result\n    return self.__get_result()\n  File "C:\\Users\\Ian\\anaconda3\\envs\\qlbt\\lib\\concurrent\\futures\\_base.py", line 389, in __get_result\n    raise self._exception\n  File "C:\\Users\\Ian\\Documents\\Financial testing\\data_pulling\\dump_bin.py", line 500, in _dump_features\n    _future.result()\n  File "C:\\Users\\Ian\\anaconda3\\envs\\qlbt\\lib\\concurrent\\futures\\_base.py", line 437, in result\n    return self.__get_result()\n  File "C:\\Users\\Ian\\anaconda3\\envs\\qlbt\\lib\\concurrent\\futures\\_base.py", line 389, in __get_result\n    raise self._exception\n  File "C:\\Users\\Ian\\Documents\\Financial testing\\data_pulling\\dump_bin.py", line 500, in _dump_features\n    _future.result()\n  File "C:\\Users\\Ian\\anaconda3\\envs\\qlbt\\lib\\concurrent\\futures\\_base.py", line 437, in result\n    return self.__get_result()\n  File "C:\\Users\\Ian\\anaconda3\\envs\\qlbt\\lib\\concurrent\\futures\\_base.py", line 389, in __get_result\n    raise self._exception\n  File "C:\\Users\\Ian\\Documents\\Financial testing\\data_pulling\\dump_bin.py", line 500, in _dump_features\n    _future.result()\n  File "C:\\Users\\Ian\\anaconda3\\envs\\qlbt\\lib\\concurrent\\futures\\_base.py", line 437, in result\n    return self.__get_result()\n  File "C:\\Users\\Ian\\anaconda3\\envs\\qlbt\\lib\\concurrent\\futures\\_base.py", line 389, in __get_result\n    raise self._exception\n  File "C:\\Users\\Ian\\Documents\\Financial testing\\data_pulling\\dump_bin.py", line 500, in _dump_features\n    _future.result()\n  File "C:\\Users\\Ian\\anaconda3\\envs\\qlbt\\lib\\concurrent\\futures\\_base.py", line 437, in result\n    return self.__get_result()\n  File "C:\\Users\\Ian\\anaconda3\\envs\\qlbt\\lib\\concurrent\\futures\\_base.py", line 389, in __get_result\n    raise self._exception\n  File "C:\\Users\\Ian\\Documents\\Financial testing\\data_pulling\\dump_bin.py", line 500, in _dump_features\n    _future.result()\n  File "C:\\Users\\Ian\\anaconda3\\envs\\qlbt\\lib\\concurrent\\futures\\_base.py", line 437, in result\n    return self.__get_result()\n  File "C:\\Users\\Ian\\anaconda3\\envs\\qlbt\\lib\\concurrent\\futures\\_base.py", line 389, in __get_result\n    raise self._exception\n  File "C:\\Users\\Ian\\Documents\\Financial testing\\data_pulling\\dump_bin.py", line 500, in _dump_features\n    _future.result()\n  File "C:\\Users\\Ian\\anaconda3\\envs\\qlbt\\lib\\concurrent\\futures\\_base.py", line 437, in result\n    return self.__get_result()\n  File "C:\\Users\\Ian\\anaconda3\\envs\\qlbt\\lib\\concurrent\\futures\\_base.py", line 389, in __get_result\n    raise self._exception\n  File "C:\\Users\\Ian\\Documents\\Financial testing\\data_pulling\\dump_bin.py", line 500, in _dump_features\n    _future.result()\n  File "C:\\Users\\Ian\\anaconda3\\envs\\qlbt\\lib\\concurrent\\futures\\_base.py", line 437, in result\n    return self.__get_result()\n  File "C:\\Users\\Ian\\anaconda3\\envs\\qlbt\\lib\\concurrent\\futures\\_base.py", line 389, in __get_result\n    raise self._exception\n  File "C:\\Users\\Ian\\Documents\\Financial testing\\data_pulling\\dump_bin.py", line 500, in _dump_features\n    _future.result()\n  File "C:\\Users\\Ian\\anaconda3\\envs\\qlbt\\lib\\concurrent\\futures\\_base.py", line 437, in result\n    return self.__get_result()\n  File "C:\\Users\\Ian\\anaconda3\\envs\\qlbt\\lib\\concurrent\\futures\\_base.py", line 389, in __get_result\n    raise self._exception\n  File "C:\\Users\\Ian\\Documents\\Financial testing\\data_pulling\\dump_bin.py", line 500, in _dump_features\n    _future.result()\n  File "C:\\Users\\Ian\\anaconda3\\envs\\qlbt\\lib\\concurrent\\futures\\_base.py", line 437, in result\n    return self.__get_result()\n  File "C:\\Users\\Ian\\anaconda3\\envs\\qlbt\\lib\\concurrent\\futures\\_base.py", line 389, in __get_result\n    raise self._exception\n  File "C:\\Users\\Ian\\Documents\\Financial testing\\data_pulling\\dump_bin.py", line 500, in _dump_features\n    _future.result()\n  File "C:\\Users\\Ian\\anaconda3\\envs\\qlbt\\lib\\concurrent\\futures\\_base.py", line 437, in result\n    return self.__get_result()\n  File "C:\\Users\\Ian\\anaconda3\\envs\\qlbt\\lib\\concurrent\\futures\\_base.py", line 389, in __get_result\n    raise self._exception\n  File "C:\\Users\\Ian\\Documents\\Financial testing\\data_pulling\\dump_bin.py", line 500, in _dump_features\n    _future.result()\n  File "C:\\Users\\Ian\\anaconda3\\envs\\qlbt\\lib\\concurrent\\futures\\_base.py", line 437, in result\n    return self.__get_result()\n  File "C:\\Users\\Ian\\anaconda3\\envs\\qlbt\\lib\\concurrent\\futures\\_base.py", line 389, in __get_result\n    raise self._exception\n  File "C:\\Users\\Ian\\Documents\\Financial testing\\data_pulling\\dump_bin.py", line 500, in _dump_features\n    _future.result()\n  File "C:\\Users\\Ian\\anaconda3\\envs\\qlbt\\lib\\concurrent\\futures\\_base.py", line 437, in result\n    return self.__get_result()\n  File "C:\\Users\\Ian\\anaconda3\\envs\\qlbt\\lib\\concurrent\\futures\\_base.py", line 389, in __get_result\n    raise self._exception\n  File "C:\\Users\\Ian\\Documents\\Financial testing\\data_pulling\\dump_bin.py", line 500, in _dump_features\n    _future.result()\n  File "C:\\Users\\Ian\\anaconda3\\envs\\qlbt\\lib\\concurrent\\futures\\_base.py", line 437, in result\n    return self.__get_result()\n  File "C:\\Users\\Ian\\anaconda3\\envs\\qlbt\\lib\\concurrent\\futures\\_base.py", line 389, in __get_result\n    raise self._exception\n  File "C:\\Users\\Ian\\Documents\\Financial testing\\data_pulling\\dump_bin.py", line 500, in _dump_features\n    _future.result()\n  File "C:\\Users\\Ian\\anaconda3\\envs\\qlbt\\lib\\concurrent\\futures\\_base.py", line 437, in result\n    return self.__get_result()\n  File "C:\\Users\\Ian\\anaconda3\\envs\\qlbt\\lib\\concurrent\\futures\\_base.py", line 389, in __get_result\n    raise self._exception\n  File "C:\\Users\\Ian\\Documents\\Financial testing\\data_pulling\\dump_bin.py", line 500, in _dump_features\n    _future.result()\n  File "C:\\Users\\Ian\\anaconda3\\envs\\qlbt\\lib\\concurrent\\futures\\_base.py", line 437, in result\n    return self.__get_result()\n  File "C:\\Users\\Ian\\anaconda3\\envs\\qlbt\\lib\\concurrent\\futures\\_base.py", line 389, in __get_result\n    raise self._exception\n  File "C:\\Users\\Ian\\Documents\\Financial testing\\data_pulling\\dump_bin.py", line 500, in _dump_features\n    _future.result()\n  File "C:\\Users\\Ian\\anaconda3\\envs\\qlbt\\lib\\concurrent\\futures\\_base.py", line 437, in result\n    return self.__get_result()\n  File "C:\\Users\\Ian\\anaconda3\\envs\\qlbt\\lib\\concurrent\\futures\\_base.py", line 389, in __get_result\n    raise self._exception\n  File "C:\\Users\\Ian\\Documents\\Financial testing\\data_pulling\\dump_bin.py", line 500, in _dump_features\n    _future.result()\n  File "C:\\Users\\Ian\\anaconda3\\envs\\qlbt\\lib\\concurrent\\futures\\_base.py", line 437, in result\n    return self.__get_result()\n  File "C:\\Users\\Ian\\anaconda3\\envs\\qlbt\\lib\\concurrent\\futures\\_base.py", line 389, in __get_result\n    raise self._exception\nconcurrent.futures.process.BrokenProcessPool: A process in the process pool was terminated abruptly while the future was running or pending.\n', 'WAXPBUSD': 'Traceback (most recent call last):\n  File "C:\\Users\\Ian\\Documents\\Financial testing\\data_pulling\\dump_bin.py", line 500, in _dump_features\n    _future.result()\n  File "C:\\Users\\Ian\\anaconda3\\envs\\qlbt\\lib\\concurrent\\futures\\_base.py", line 437, in result\n    return self.__get_result()\n  File "C:\\Users\\Ian\\anaconda3\\envs\\qlbt\\lib\\concurrent\\futures\\_base.py", line 389, in __get_result\n    raise self._exception\n  File "C:\\Users\\Ian\\Documents\\Financial testing\\data_pulling\\dump_bin.py", line 500, in _dump_features\n    _future.result()\n  File "C:\\Users\\Ian\\anaconda3\\envs\\qlbt\\lib\\concurrent\\futures\\_base.py", line 437, in result\n    return self.__get_result()\n  File "C:\\Users\\Ian\\anaconda3\\envs\\qlbt\\lib\\concurrent\\futures\\_base.py", line 389, in __get_result\n    raise self._exception\n  File "C:\\Users\\Ian\\Documents\\Financial testing\\data_pulling\\dump_bin.py", line 500, in _dump_features\n    _future.result()\n  File "C:\\Users\\Ian\\anaconda3\\envs\\qlbt\\lib\\concurrent\\futures\\_base.py", line 437, in result\n    return self.__get_result()\n  File "C:\\Users\\Ian\\anaconda3\\envs\\qlbt\\lib\\concurrent\\futures\\_base.py", line 389, in __get_result\n    raise self._exception\n  File "C:\\Users\\Ian\\Documents\\Financial testing\\data_pulling\\dump_bin.py", line 500, in _dump_features\n    _future.result()\n  File "C:\\Users\\Ian\\anaconda3\\envs\\qlbt\\lib\\concurrent\\futures\\_base.py", line 437, in result\n    return self.__get_result()\n  File "C:\\Users\\Ian\\anaconda3\\envs\\qlbt\\lib\\concurrent\\futures\\_base.py", line 389, in __get_result\n    raise self._exception\n  File "C:\\Users\\Ian\\Documents\\Financial testing\\data_pulling\\dump_bin.py", line 500, in _dump_features\n    _future.result()\n  File "C:\\Users\\Ian\\anaconda3\\envs\\qlbt\\lib\\concurrent\\futures\\_base.py", line 437, in result\n    return self.__get_result()\n  File "C:\\Users\\Ian\\anaconda3\\envs\\qlbt\\lib\\concurrent\\futures\\_base.py", line 389, in __get_result\n    raise self._exception\n  File "C:\\Users\\Ian\\Documents\\Financial testing\\data_pulling\\dump_bin.py", line 500, in _dump_features\n    _future.result()\n  File "C:\\Users\\Ian\\anaconda3\\envs\\qlbt\\lib\\concurrent\\futures\\_base.py", line 437, in result\n    return self.__get_result()\n  File "C:\\Users\\Ian\\anaconda3\\envs\\qlbt\\lib\\concurrent\\futures\\_base.py", line 389, in __get_result\n    raise self._exception\n  File "C:\\Users\\Ian\\Documents\\Financial testing\\data_pulling\\dump_bin.py", line 500, in _dump_features\n    _future.result()\n  File "C:\\Users\\Ian\\anaconda3\\envs\\qlbt\\lib\\concurrent\\futures\\_base.py", line 437, in result\n    return self.__get_result()\n  File "C:\\Users\\Ian\\anaconda3\\envs\\qlbt\\lib\\concurrent\\futures\\_base.py", line 389, in __get_result\n    raise self._exception\n  File "C:\\Users\\Ian\\Documents\\Financial testing\\data_pulling\\dump_bin.py", line 500, in _dump_features\n    _future.result()\n  File "C:\\Users\\Ian\\anaconda3\\envs\\qlbt\\lib\\concurrent\\futures\\_base.py", line 437, in result\n    return self.__get_result()\n  File "C:\\Users\\Ian\\anaconda3\\envs\\qlbt\\lib\\concurrent\\futures\\_base.py", line 389, in __get_result\n    raise self._exception\n  File "C:\\Users\\Ian\\Documents\\Financial testing\\data_pulling\\dump_bin.py", line 500, in _dump_features\n    _future.result()\n  File "C:\\Users\\Ian\\anaconda3\\envs\\qlbt\\lib\\concurrent\\futures\\_base.py", line 437, in result\n    return self.__get_result()\n  File "C:\\Users\\Ian\\anaconda3\\envs\\qlbt\\lib\\concurrent\\futures\\_base.py", line 389, in __get_result\n    raise self._exception\n  File "C:\\Users\\Ian\\Documents\\Financial testing\\data_pulling\\dump_bin.py", line 500, in _dump_features\n    _future.result()\n  File "C:\\Users\\Ian\\anaconda3\\envs\\qlbt\\lib\\concurrent\\futures\\_base.py", line 437, in result\n    return self.__get_result()\n  File "C:\\Users\\Ian\\anaconda3\\envs\\qlbt\\lib\\concurrent\\futures\\_base.py", line 389, in __get_result\n    raise self._exception\n  File "C:\\Users\\Ian\\Documents\\Financial testing\\data_pulling\\dump_bin.py", line 500, in _dump_features\n    _future.result()\n  File "C:\\Users\\Ian\\anaconda3\\envs\\qlbt\\lib\\concurrent\\futures\\_base.py", line 437, in result\n    return self.__get_result()\n  File "C:\\Users\\Ian\\anaconda3\\envs\\qlbt\\lib\\concurrent\\futures\\_base.py", line 389, in __get_result\n    raise self._exception\n  File "C:\\Users\\Ian\\Documents\\Financial testing\\data_pulling\\dump_bin.py", line 500, in _dump_features\n    _future.result()\n  File "C:\\Users\\Ian\\anaconda3\\envs\\qlbt\\lib\\concurrent\\futures\\_base.py", line 437, in result\n    return self.__get_result()\n  File "C:\\Users\\Ian\\anaconda3\\envs\\qlbt\\lib\\concurrent\\futures\\_base.py", line 389, in __get_result\n    raise self._exception\n  File "C:\\Users\\Ian\\Documents\\Financial testing\\data_pulling\\dump_bin.py", line 500, in _dump_features\n    _future.result()\n  File "C:\\Users\\Ian\\anaconda3\\envs\\qlbt\\lib\\concurrent\\futures\\_base.py", line 437, in result\n    return self.__get_result()\n  File "C:\\Users\\Ian\\anaconda3\\envs\\qlbt\\lib\\concurrent\\futures\\_base.py", line 389, in __get_result\n    raise self._exception\n  File "C:\\Users\\Ian\\Documents\\Financial testing\\data_pulling\\dump_bin.py", line 500, in _dump_features\n    _future.result()\n  File "C:\\Users\\Ian\\anaconda3\\envs\\qlbt\\lib\\concurrent\\futures\\_base.py", line 437, in result\n    return self.__get_result()\n  File "C:\\Users\\Ian\\anaconda3\\envs\\qlbt\\lib\\concurrent\\futures\\_base.py", line 389, in __get_result\n    raise self._exception\n  File "C:\\Users\\Ian\\Documents\\Financial testing\\data_pulling\\dump_bin.py", line 500, in _dump_features\n    _future.result()\n  File "C:\\Users\\Ian\\anaconda3\\envs\\qlbt\\lib\\concurrent\\futures\\_base.py", line 437, in result\n    return self.__get_result()\n  File "C:\\Users\\Ian\\anaconda3\\envs\\qlbt\\lib\\concurrent\\futures\\_base.py", line 389, in __get_result\n    raise self._exception\n  File "C:\\Users\\Ian\\Documents\\Financial testing\\data_pulling\\dump_bin.py", line 500, in _dump_features\n    _future.result()\n  File "C:\\Users\\Ian\\anaconda3\\envs\\qlbt\\lib\\concurrent\\futures\\_base.py", line 437, in result\n    return self.__get_result()\n  File "C:\\Users\\Ian\\anaconda3\\envs\\qlbt\\lib\\concurrent\\futures\\_base.py", line 389, in __get_result\n    raise self._exception\n  File "C:\\Users\\Ian\\Documents\\Financial testing\\data_pulling\\dump_bin.py", line 500, in _dump_features\n    _future.result()\n  File "C:\\Users\\Ian\\anaconda3\\envs\\qlbt\\lib\\concurrent\\futures\\_base.py", line 437, in result\n    return self.__get_result()\n  File "C:\\Users\\Ian\\anaconda3\\envs\\qlbt\\lib\\concurrent\\futures\\_base.py", line 389, in __get_result\n    raise self._exception\n  File "C:\\Users\\Ian\\Documents\\Financial testing\\data_pulling\\dump_bin.py", line 500, in _dump_features\n    _future.result()\n  File "C:\\Users\\Ian\\anaconda3\\envs\\qlbt\\lib\\concurrent\\futures\\_base.py", line 437, in result\n    return self.__get_result()\n  File "C:\\Users\\Ian\\anaconda3\\envs\\qlbt\\lib\\concurrent\\futures\\_base.py", line 389, in __get_result\n    raise self._exception\n  File "C:\\Users\\Ian\\Documents\\Financial testing\\data_pulling\\dump_bin.py", line 500, in _dump_features\n    _future.result()\n  File "C:\\Users\\Ian\\anaconda3\\envs\\qlbt\\lib\\concurrent\\futures\\_base.py", line 437, in result\n    return self.__get_result()\n  File "C:\\Users\\Ian\\anaconda3\\envs\\qlbt\\lib\\concurrent\\futures\\_base.py", line 389, in __get_result\n    raise self._exception\nconcurrent.futures.process.BrokenProcessPool: A process in the process pool was terminated abruptly while the future was running or pending.\n'}
